[2024-02-27T13:48:15.288+0000] {taskinstance.py:1957} INFO - Dependencies all met for dep_context=non-requeueable deps ti=<TaskInstance: tsunami_etl.extract_task scheduled__2024-01-01T13:00:00+00:00 [queued]>
[2024-02-27T13:48:15.291+0000] {taskinstance.py:1957} INFO - Dependencies all met for dep_context=requeueable deps ti=<TaskInstance: tsunami_etl.extract_task scheduled__2024-01-01T13:00:00+00:00 [queued]>
[2024-02-27T13:48:15.291+0000] {taskinstance.py:2171} INFO - Starting attempt 1 of 2
[2024-02-27T13:48:15.297+0000] {taskinstance.py:2192} INFO - Executing <Task(PythonOperator): extract_task> on 2024-01-01 13:00:00+00:00
[2024-02-27T13:48:15.302+0000] {standard_task_runner.py:60} INFO - Started process 618 to run task
[2024-02-27T13:48:15.305+0000] {standard_task_runner.py:87} INFO - Running: ['airflow', 'tasks', 'run', 'tsunami_etl', 'extract_task', 'scheduled__2024-01-01T13:00:00+00:00', '--job-id', '32', '--raw', '--subdir', 'DAGS_FOLDER/bbc_news_etl.py', '--cfg-path', '/tmp/tmpu1e02y2y']
[2024-02-27T13:48:15.306+0000] {standard_task_runner.py:88} INFO - Job 32: Subtask extract_task
[2024-02-27T13:48:15.327+0000] {task_command.py:423} INFO - Running <TaskInstance: tsunami_etl.extract_task scheduled__2024-01-01T13:00:00+00:00 [running]> on host 169dadc36ff0
[2024-02-27T13:48:15.352+0000] {taskinstance.py:2481} INFO - Exporting env vars: AIRFLOW_CTX_DAG_OWNER='airflow' AIRFLOW_CTX_DAG_ID='tsunami_etl' AIRFLOW_CTX_TASK_ID='extract_task' AIRFLOW_CTX_EXECUTION_DATE='2024-01-01T13:00:00+00:00' AIRFLOW_CTX_TRY_NUMBER='1' AIRFLOW_CTX_DAG_RUN_ID='scheduled__2024-01-01T13:00:00+00:00'
[2024-02-27T13:48:15.567+0000] {_metadata.py:139} WARNING - Compute Engine Metadata server unavailable on attempt 1 of 3. Reason: [Errno 111] Connection refused
[2024-02-27T13:48:15.568+0000] {_metadata.py:139} WARNING - Compute Engine Metadata server unavailable on attempt 2 of 3. Reason: [Errno 111] Connection refused
[2024-02-27T13:48:15.569+0000] {_metadata.py:139} WARNING - Compute Engine Metadata server unavailable on attempt 3 of 3. Reason: [Errno 111] Connection refused
[2024-02-27T13:48:15.569+0000] {_default.py:338} WARNING - Authentication failed using Compute Engine authentication due to unavailable metadata server.
[2024-02-27T13:48:15.570+0000] {taskinstance.py:2699} ERROR - Task failed with exception
Traceback (most recent call last):
  File "/home/airflow/.local/lib/python3.8/site-packages/airflow/models/taskinstance.py", line 433, in _execute_task
    result = execute_callable(context=context, **execute_callable_kwargs)
  File "/home/airflow/.local/lib/python3.8/site-packages/airflow/operators/python.py", line 199, in execute
    return_value = self.execute_callable()
  File "/home/airflow/.local/lib/python3.8/site-packages/airflow/operators/python.py", line 216, in execute_callable
    return self.python_callable(*self.op_args, **self.op_kwargs)
  File "/opt/airflow/dags/bbc_news_etl.py", line 44, in extract_tsunami
    return pandas_gbq.read_gbq(query, project_id='locator-173007', dialect='standard')
  File "/home/airflow/.local/lib/python3.8/site-packages/pandas_gbq/gbq.py", line 934, in read_gbq
    connector = GbqConnector(
  File "/home/airflow/.local/lib/python3.8/site-packages/pandas_gbq/gbq.py", line 318, in __init__
    self.credentials, default_project = auth.get_credentials(
  File "/home/airflow/.local/lib/python3.8/site-packages/pandas_gbq/auth.py", line 56, in get_credentials
    credentials, default_project_id = pydata_google_auth.default(
  File "/home/airflow/.local/lib/python3.8/site-packages/pydata_google_auth/auth.py", line 152, in default
    credentials = get_user_credentials(
  File "/home/airflow/.local/lib/python3.8/site-packages/pydata_google_auth/auth.py", line 362, in get_user_credentials
    credentials = _webserver.run_local_server(app_flow, **AUTH_URI_KWARGS)
  File "/home/airflow/.local/lib/python3.8/site-packages/pydata_google_auth/_webserver.py", line 89, in run_local_server
    return app_flow.run_local_server(host=LOCALHOST, port=port, **kwargs)
  File "/home/airflow/.local/lib/python3.8/site-packages/google_auth_oauthlib/flow.py", line 444, in run_local_server
    webbrowser.get(browser).open(auth_url, new=1, autoraise=True)
  File "/usr/local/lib/python3.8/webbrowser.py", line 65, in get
    raise Error("could not locate runnable browser")
webbrowser.Error: could not locate runnable browser
[2024-02-27T13:48:15.574+0000] {taskinstance.py:1138} INFO - Marking task as UP_FOR_RETRY. dag_id=tsunami_etl, task_id=extract_task, execution_date=20240101T130000, start_date=20240227T134815, end_date=20240227T134815
[2024-02-27T13:48:15.579+0000] {standard_task_runner.py:107} ERROR - Failed to execute job 32 for task extract_task (could not locate runnable browser; 618)
[2024-02-27T13:48:15.589+0000] {local_task_job_runner.py:234} INFO - Task exited with return code 1
[2024-02-27T13:48:15.599+0000] {taskinstance.py:3281} INFO - 0 downstream tasks scheduled from follow-on schedule check
[2024-02-27T17:00:15.826+0000] {taskinstance.py:1957} INFO - Dependencies all met for dep_context=non-requeueable deps ti=<TaskInstance: tsunami_etl.extract_task scheduled__2024-01-01T13:00:00+00:00 [queued]>
[2024-02-27T17:00:15.828+0000] {taskinstance.py:1957} INFO - Dependencies all met for dep_context=requeueable deps ti=<TaskInstance: tsunami_etl.extract_task scheduled__2024-01-01T13:00:00+00:00 [queued]>
[2024-02-27T17:00:15.829+0000] {taskinstance.py:2171} INFO - Starting attempt 1 of 2
[2024-02-27T17:00:15.834+0000] {taskinstance.py:2192} INFO - Executing <Task(PythonOperator): extract_task> on 2024-01-01 13:00:00+00:00
[2024-02-27T17:00:15.837+0000] {standard_task_runner.py:60} INFO - Started process 391 to run task
[2024-02-27T17:00:15.840+0000] {standard_task_runner.py:87} INFO - Running: ['airflow', 'tasks', 'run', 'tsunami_etl', 'extract_task', 'scheduled__2024-01-01T13:00:00+00:00', '--job-id', '16', '--raw', '--subdir', 'DAGS_FOLDER/tsunami_etl.py', '--cfg-path', '/tmp/tmpw98n5b1p']
[2024-02-27T17:00:15.842+0000] {standard_task_runner.py:88} INFO - Job 16: Subtask extract_task
[2024-02-27T17:00:15.861+0000] {task_command.py:423} INFO - Running <TaskInstance: tsunami_etl.extract_task scheduled__2024-01-01T13:00:00+00:00 [running]> on host 45e004960ef9
[2024-02-27T17:00:15.885+0000] {taskinstance.py:2481} INFO - Exporting env vars: AIRFLOW_CTX_DAG_OWNER='airflow' AIRFLOW_CTX_DAG_ID='tsunami_etl' AIRFLOW_CTX_TASK_ID='extract_task' AIRFLOW_CTX_EXECUTION_DATE='2024-01-01T13:00:00+00:00' AIRFLOW_CTX_TRY_NUMBER='1' AIRFLOW_CTX_DAG_RUN_ID='scheduled__2024-01-01T13:00:00+00:00'
[2024-02-27T17:00:15.886+0000] {taskinstance.py:2699} ERROR - Task failed with exception
Traceback (most recent call last):
  File "/home/airflow/.local/lib/python3.8/site-packages/airflow/models/taskinstance.py", line 433, in _execute_task
    result = execute_callable(context=context, **execute_callable_kwargs)
  File "/home/airflow/.local/lib/python3.8/site-packages/airflow/operators/python.py", line 199, in execute
    return_value = self.execute_callable()
  File "/home/airflow/.local/lib/python3.8/site-packages/airflow/operators/python.py", line 216, in execute_callable
    return self.python_callable(*self.op_args, **self.op_kwargs)
  File "/opt/airflow/dags/tsunami_etl.py", line 46, in extract_tsunami
    GCPCredentials = service_account.Credentials.from_service_account_file(f"../auth/json/{CREDENTIALS_FILE}")
  File "/home/airflow/.local/lib/python3.8/site-packages/google/oauth2/service_account.py", line 257, in from_service_account_file
    info, signer = _service_account_info.from_filename(
  File "/home/airflow/.local/lib/python3.8/site-packages/google/auth/_service_account_info.py", line 78, in from_filename
    with io.open(filename, "r", encoding="utf-8") as json_file:
FileNotFoundError: [Errno 2] No such file or directory: '../auth/json/None'
[2024-02-27T17:00:15.889+0000] {taskinstance.py:1138} INFO - Marking task as UP_FOR_RETRY. dag_id=tsunami_etl, task_id=extract_task, execution_date=20240101T130000, start_date=20240227T170015, end_date=20240227T170015
[2024-02-27T17:00:15.892+0000] {standard_task_runner.py:107} ERROR - Failed to execute job 16 for task extract_task ([Errno 2] No such file or directory: '../auth/json/None'; 391)
[2024-02-27T17:00:15.900+0000] {local_task_job_runner.py:234} INFO - Task exited with return code 1
[2024-02-27T17:00:15.909+0000] {taskinstance.py:3281} INFO - 0 downstream tasks scheduled from follow-on schedule check
[2024-02-27T17:04:32.363+0000] {taskinstance.py:1957} INFO - Dependencies all met for dep_context=non-requeueable deps ti=<TaskInstance: tsunami_etl.extract_task scheduled__2024-01-01T13:00:00+00:00 [queued]>
[2024-02-27T17:04:32.366+0000] {taskinstance.py:1957} INFO - Dependencies all met for dep_context=requeueable deps ti=<TaskInstance: tsunami_etl.extract_task scheduled__2024-01-01T13:00:00+00:00 [queued]>
[2024-02-27T17:04:32.366+0000] {taskinstance.py:2171} INFO - Starting attempt 1 of 2
[2024-02-27T17:04:32.375+0000] {taskinstance.py:2192} INFO - Executing <Task(PythonOperator): extract_task> on 2024-01-01 13:00:00+00:00
[2024-02-27T17:04:32.383+0000] {standard_task_runner.py:60} INFO - Started process 600 to run task
[2024-02-27T17:04:32.386+0000] {standard_task_runner.py:87} INFO - Running: ['airflow', 'tasks', 'run', 'tsunami_etl', 'extract_task', 'scheduled__2024-01-01T13:00:00+00:00', '--job-id', '31', '--raw', '--subdir', 'DAGS_FOLDER/tsunami_etl.py', '--cfg-path', '/tmp/tmp5yh1jkob']
[2024-02-27T17:04:32.389+0000] {standard_task_runner.py:88} INFO - Job 31: Subtask extract_task
[2024-02-27T17:04:32.416+0000] {task_command.py:423} INFO - Running <TaskInstance: tsunami_etl.extract_task scheduled__2024-01-01T13:00:00+00:00 [running]> on host 45e004960ef9
[2024-02-27T17:04:32.446+0000] {taskinstance.py:2481} INFO - Exporting env vars: AIRFLOW_CTX_DAG_OWNER='airflow' AIRFLOW_CTX_DAG_ID='tsunami_etl' AIRFLOW_CTX_TASK_ID='extract_task' AIRFLOW_CTX_EXECUTION_DATE='2024-01-01T13:00:00+00:00' AIRFLOW_CTX_TRY_NUMBER='1' AIRFLOW_CTX_DAG_RUN_ID='scheduled__2024-01-01T13:00:00+00:00'
[2024-02-27T17:04:32.447+0000] {taskinstance.py:2699} ERROR - Task failed with exception
Traceback (most recent call last):
  File "/home/airflow/.local/lib/python3.8/site-packages/airflow/models/taskinstance.py", line 433, in _execute_task
    result = execute_callable(context=context, **execute_callable_kwargs)
  File "/home/airflow/.local/lib/python3.8/site-packages/airflow/operators/python.py", line 199, in execute
    return_value = self.execute_callable()
  File "/home/airflow/.local/lib/python3.8/site-packages/airflow/operators/python.py", line 216, in execute_callable
    return self.python_callable(*self.op_args, **self.op_kwargs)
  File "/opt/airflow/dags/tsunami_etl.py", line 42, in extract_tsunami
    GCPCredentials = service_account.Credentials.from_service_account_file(f"../auth/json/{CREDENTIALS_FILE}")
  File "/home/airflow/.local/lib/python3.8/site-packages/google/oauth2/service_account.py", line 257, in from_service_account_file
    info, signer = _service_account_info.from_filename(
  File "/home/airflow/.local/lib/python3.8/site-packages/google/auth/_service_account_info.py", line 78, in from_filename
    with io.open(filename, "r", encoding="utf-8") as json_file:
FileNotFoundError: [Errno 2] No such file or directory: '../auth/json/None'
[2024-02-27T17:04:32.450+0000] {taskinstance.py:1138} INFO - Marking task as UP_FOR_RETRY. dag_id=tsunami_etl, task_id=extract_task, execution_date=20240101T130000, start_date=20240227T170432, end_date=20240227T170432
[2024-02-27T17:04:32.455+0000] {standard_task_runner.py:107} ERROR - Failed to execute job 31 for task extract_task ([Errno 2] No such file or directory: '../auth/json/None'; 600)
[2024-02-27T17:04:32.484+0000] {local_task_job_runner.py:234} INFO - Task exited with return code 1
[2024-02-27T17:04:32.496+0000] {taskinstance.py:3281} INFO - 0 downstream tasks scheduled from follow-on schedule check
[2024-02-27T17:06:36.090+0000] {taskinstance.py:1957} INFO - Dependencies all met for dep_context=non-requeueable deps ti=<TaskInstance: tsunami_etl.extract_task scheduled__2024-01-01T13:00:00+00:00 [queued]>
[2024-02-27T17:06:36.093+0000] {taskinstance.py:1957} INFO - Dependencies all met for dep_context=requeueable deps ti=<TaskInstance: tsunami_etl.extract_task scheduled__2024-01-01T13:00:00+00:00 [queued]>
[2024-02-27T17:06:36.093+0000] {taskinstance.py:2171} INFO - Starting attempt 1 of 2
[2024-02-27T17:06:36.099+0000] {taskinstance.py:2192} INFO - Executing <Task(PythonOperator): extract_task> on 2024-01-01 13:00:00+00:00
[2024-02-27T17:06:36.102+0000] {standard_task_runner.py:60} INFO - Started process 792 to run task
[2024-02-27T17:06:36.104+0000] {standard_task_runner.py:87} INFO - Running: ['airflow', 'tasks', 'run', 'tsunami_etl', 'extract_task', 'scheduled__2024-01-01T13:00:00+00:00', '--job-id', '47', '--raw', '--subdir', 'DAGS_FOLDER/tsunami_etl.py', '--cfg-path', '/tmp/tmpqzmmbak9']
[2024-02-27T17:06:36.105+0000] {standard_task_runner.py:88} INFO - Job 47: Subtask extract_task
[2024-02-27T17:06:36.122+0000] {task_command.py:423} INFO - Running <TaskInstance: tsunami_etl.extract_task scheduled__2024-01-01T13:00:00+00:00 [running]> on host 45e004960ef9
[2024-02-27T17:06:36.145+0000] {taskinstance.py:2481} INFO - Exporting env vars: AIRFLOW_CTX_DAG_OWNER='airflow' AIRFLOW_CTX_DAG_ID='tsunami_etl' AIRFLOW_CTX_TASK_ID='extract_task' AIRFLOW_CTX_EXECUTION_DATE='2024-01-01T13:00:00+00:00' AIRFLOW_CTX_TRY_NUMBER='1' AIRFLOW_CTX_DAG_RUN_ID='scheduled__2024-01-01T13:00:00+00:00'
[2024-02-27T17:06:36.146+0000] {taskinstance.py:2699} ERROR - Task failed with exception
Traceback (most recent call last):
  File "/home/airflow/.local/lib/python3.8/site-packages/airflow/models/taskinstance.py", line 433, in _execute_task
    result = execute_callable(context=context, **execute_callable_kwargs)
  File "/home/airflow/.local/lib/python3.8/site-packages/airflow/operators/python.py", line 199, in execute
    return_value = self.execute_callable()
  File "/home/airflow/.local/lib/python3.8/site-packages/airflow/operators/python.py", line 216, in execute_callable
    return self.python_callable(*self.op_args, **self.op_kwargs)
  File "/opt/airflow/dags/tsunami_etl.py", line 42, in extract_tsunami
    GCPCredentials = service_account.Credentials.from_service_account_file(f"../auth/json/credentials.json")
  File "/home/airflow/.local/lib/python3.8/site-packages/google/oauth2/service_account.py", line 257, in from_service_account_file
    info, signer = _service_account_info.from_filename(
  File "/home/airflow/.local/lib/python3.8/site-packages/google/auth/_service_account_info.py", line 78, in from_filename
    with io.open(filename, "r", encoding="utf-8") as json_file:
FileNotFoundError: [Errno 2] No such file or directory: '../auth/json/credentials.json'
[2024-02-27T17:06:36.148+0000] {taskinstance.py:1138} INFO - Marking task as UP_FOR_RETRY. dag_id=tsunami_etl, task_id=extract_task, execution_date=20240101T130000, start_date=20240227T170636, end_date=20240227T170636
[2024-02-27T17:06:36.152+0000] {standard_task_runner.py:107} ERROR - Failed to execute job 47 for task extract_task ([Errno 2] No such file or directory: '../auth/json/credentials.json'; 792)
[2024-02-27T17:06:36.162+0000] {local_task_job_runner.py:234} INFO - Task exited with return code 1
[2024-02-27T17:06:36.171+0000] {taskinstance.py:3281} INFO - 0 downstream tasks scheduled from follow-on schedule check
[2024-02-27T17:10:04.892+0000] {taskinstance.py:1957} INFO - Dependencies all met for dep_context=non-requeueable deps ti=<TaskInstance: tsunami_etl.extract_task scheduled__2024-01-01T13:00:00+00:00 [queued]>
[2024-02-27T17:10:04.896+0000] {taskinstance.py:1957} INFO - Dependencies all met for dep_context=requeueable deps ti=<TaskInstance: tsunami_etl.extract_task scheduled__2024-01-01T13:00:00+00:00 [queued]>
[2024-02-27T17:10:04.896+0000] {taskinstance.py:2171} INFO - Starting attempt 1 of 2
[2024-02-27T17:10:04.902+0000] {taskinstance.py:2192} INFO - Executing <Task(PythonOperator): extract_task> on 2024-01-01 13:00:00+00:00
[2024-02-27T17:10:04.911+0000] {standard_task_runner.py:60} INFO - Started process 991 to run task
[2024-02-27T17:10:04.913+0000] {standard_task_runner.py:87} INFO - Running: ['airflow', 'tasks', 'run', 'tsunami_etl', 'extract_task', 'scheduled__2024-01-01T13:00:00+00:00', '--job-id', '15', '--raw', '--subdir', 'DAGS_FOLDER/tsunami_etl.py', '--cfg-path', '/tmp/tmpzlu_hgxx']
[2024-02-27T17:10:04.915+0000] {standard_task_runner.py:88} INFO - Job 15: Subtask extract_task
[2024-02-27T17:10:04.933+0000] {task_command.py:423} INFO - Running <TaskInstance: tsunami_etl.extract_task scheduled__2024-01-01T13:00:00+00:00 [running]> on host 45e004960ef9
[2024-02-27T17:10:04.956+0000] {taskinstance.py:2481} INFO - Exporting env vars: AIRFLOW_CTX_DAG_OWNER='airflow' AIRFLOW_CTX_DAG_ID='tsunami_etl' AIRFLOW_CTX_TASK_ID='extract_task' AIRFLOW_CTX_EXECUTION_DATE='2024-01-01T13:00:00+00:00' AIRFLOW_CTX_TRY_NUMBER='1' AIRFLOW_CTX_DAG_RUN_ID='scheduled__2024-01-01T13:00:00+00:00'
[2024-02-27T17:10:04.957+0000] {taskinstance.py:2699} ERROR - Task failed with exception
Traceback (most recent call last):
  File "/home/airflow/.local/lib/python3.8/site-packages/airflow/models/taskinstance.py", line 433, in _execute_task
    result = execute_callable(context=context, **execute_callable_kwargs)
  File "/home/airflow/.local/lib/python3.8/site-packages/airflow/operators/python.py", line 199, in execute
    return_value = self.execute_callable()
  File "/home/airflow/.local/lib/python3.8/site-packages/airflow/operators/python.py", line 216, in execute_callable
    return self.python_callable(*self.op_args, **self.op_kwargs)
  File "/opt/airflow/dags/tsunami_etl.py", line 41, in extract_tsunami
    GCPCredentials = service_account.Credentials.from_service_account_file("credentials.json")
  File "/home/airflow/.local/lib/python3.8/site-packages/google/oauth2/service_account.py", line 257, in from_service_account_file
    info, signer = _service_account_info.from_filename(
  File "/home/airflow/.local/lib/python3.8/site-packages/google/auth/_service_account_info.py", line 78, in from_filename
    with io.open(filename, "r", encoding="utf-8") as json_file:
FileNotFoundError: [Errno 2] No such file or directory: 'credentials.json'
[2024-02-27T17:10:04.959+0000] {taskinstance.py:1138} INFO - Marking task as UP_FOR_RETRY. dag_id=tsunami_etl, task_id=extract_task, execution_date=20240101T130000, start_date=20240227T171004, end_date=20240227T171004
[2024-02-27T17:10:04.963+0000] {standard_task_runner.py:107} ERROR - Failed to execute job 15 for task extract_task ([Errno 2] No such file or directory: 'credentials.json'; 991)
[2024-02-27T17:10:04.973+0000] {local_task_job_runner.py:234} INFO - Task exited with return code 1
[2024-02-27T17:10:04.982+0000] {taskinstance.py:3281} INFO - 0 downstream tasks scheduled from follow-on schedule check
[2024-02-27T18:10:08.367+0000] {taskinstance.py:1957} INFO - Dependencies all met for dep_context=non-requeueable deps ti=<TaskInstance: tsunami_etl.extract_task scheduled__2024-01-01T13:00:00+00:00 [queued]>
[2024-02-27T18:10:08.369+0000] {taskinstance.py:1957} INFO - Dependencies all met for dep_context=requeueable deps ti=<TaskInstance: tsunami_etl.extract_task scheduled__2024-01-01T13:00:00+00:00 [queued]>
[2024-02-27T18:10:08.369+0000] {taskinstance.py:2171} INFO - Starting attempt 1 of 2
[2024-02-27T18:10:08.375+0000] {taskinstance.py:2192} INFO - Executing <Task(PythonOperator): extract_task> on 2024-01-01 13:00:00+00:00
[2024-02-27T18:10:08.379+0000] {standard_task_runner.py:60} INFO - Started process 533 to run task
[2024-02-27T18:10:08.381+0000] {standard_task_runner.py:87} INFO - Running: ['airflow', 'tasks', 'run', 'tsunami_etl', 'extract_task', 'scheduled__2024-01-01T13:00:00+00:00', '--job-id', '41', '--raw', '--subdir', 'DAGS_FOLDER/tsunami_etl.py', '--cfg-path', '/tmp/tmpr7hifg5e']
[2024-02-27T18:10:08.383+0000] {standard_task_runner.py:88} INFO - Job 41: Subtask extract_task
[2024-02-27T18:10:08.404+0000] {task_command.py:423} INFO - Running <TaskInstance: tsunami_etl.extract_task scheduled__2024-01-01T13:00:00+00:00 [running]> on host cf5ca63d0f74
[2024-02-27T18:10:08.429+0000] {taskinstance.py:2481} INFO - Exporting env vars: AIRFLOW_CTX_DAG_OWNER='airflow' AIRFLOW_CTX_DAG_ID='tsunami_etl' AIRFLOW_CTX_TASK_ID='extract_task' AIRFLOW_CTX_EXECUTION_DATE='2024-01-01T13:00:00+00:00' AIRFLOW_CTX_TRY_NUMBER='1' AIRFLOW_CTX_DAG_RUN_ID='scheduled__2024-01-01T13:00:00+00:00'
[2024-02-27T18:10:08.429+0000] {taskinstance.py:2699} ERROR - Task failed with exception
Traceback (most recent call last):
  File "/home/airflow/.local/lib/python3.8/site-packages/airflow/models/taskinstance.py", line 433, in _execute_task
    result = execute_callable(context=context, **execute_callable_kwargs)
  File "/home/airflow/.local/lib/python3.8/site-packages/airflow/operators/python.py", line 199, in execute
    return_value = self.execute_callable()
  File "/home/airflow/.local/lib/python3.8/site-packages/airflow/operators/python.py", line 216, in execute_callable
    return self.python_callable(*self.op_args, **self.op_kwargs)
  File "/opt/airflow/dags/tsunami_etl.py", line 42, in extract_tsunami
    GCPCredentials = service_account.Credentials.from_service_account_file(credentials_path)
  File "/home/airflow/.local/lib/python3.8/site-packages/google/oauth2/service_account.py", line 257, in from_service_account_file
    info, signer = _service_account_info.from_filename(
  File "/home/airflow/.local/lib/python3.8/site-packages/google/auth/_service_account_info.py", line 78, in from_filename
    with io.open(filename, "r", encoding="utf-8") as json_file:
FileNotFoundError: [Errno 2] No such file or directory: './credentials.json'
[2024-02-27T18:10:08.432+0000] {taskinstance.py:1138} INFO - Marking task as UP_FOR_RETRY. dag_id=tsunami_etl, task_id=extract_task, execution_date=20240101T130000, start_date=20240227T181008, end_date=20240227T181008
[2024-02-27T18:10:08.436+0000] {standard_task_runner.py:107} ERROR - Failed to execute job 41 for task extract_task ([Errno 2] No such file or directory: './credentials.json'; 533)
[2024-02-27T18:10:08.481+0000] {local_task_job_runner.py:234} INFO - Task exited with return code 1
[2024-02-27T18:10:08.487+0000] {taskinstance.py:3281} INFO - 0 downstream tasks scheduled from follow-on schedule check
[2024-02-27T18:40:06.268+0000] {taskinstance.py:1957} INFO - Dependencies all met for dep_context=non-requeueable deps ti=<TaskInstance: tsunami_etl.extract_task scheduled__2024-01-01T13:00:00+00:00 [queued]>
[2024-02-27T18:40:06.272+0000] {taskinstance.py:1957} INFO - Dependencies all met for dep_context=requeueable deps ti=<TaskInstance: tsunami_etl.extract_task scheduled__2024-01-01T13:00:00+00:00 [queued]>
[2024-02-27T18:40:06.272+0000] {taskinstance.py:2171} INFO - Starting attempt 1 of 2
[2024-02-27T18:40:06.280+0000] {taskinstance.py:2192} INFO - Executing <Task(PythonOperator): extract_task> on 2024-01-01 13:00:00+00:00
[2024-02-27T18:40:06.287+0000] {standard_task_runner.py:60} INFO - Started process 1238 to run task
[2024-02-27T18:40:06.290+0000] {standard_task_runner.py:87} INFO - Running: ['airflow', 'tasks', 'run', 'tsunami_etl', 'extract_task', 'scheduled__2024-01-01T13:00:00+00:00', '--job-id', '41', '--raw', '--subdir', 'DAGS_FOLDER/tsunami_etl.py', '--cfg-path', '/tmp/tmpi3myn9hh']
[2024-02-27T18:40:06.292+0000] {standard_task_runner.py:88} INFO - Job 41: Subtask extract_task
[2024-02-27T18:40:06.313+0000] {task_command.py:423} INFO - Running <TaskInstance: tsunami_etl.extract_task scheduled__2024-01-01T13:00:00+00:00 [running]> on host f8b0167ca209
[2024-02-27T18:40:06.344+0000] {taskinstance.py:2481} INFO - Exporting env vars: AIRFLOW_CTX_DAG_OWNER='airflow' AIRFLOW_CTX_DAG_ID='tsunami_etl' AIRFLOW_CTX_TASK_ID='extract_task' AIRFLOW_CTX_EXECUTION_DATE='2024-01-01T13:00:00+00:00' AIRFLOW_CTX_TRY_NUMBER='1' AIRFLOW_CTX_DAG_RUN_ID='scheduled__2024-01-01T13:00:00+00:00'
[2024-02-27T18:40:06.345+0000] {taskinstance.py:2699} ERROR - Task failed with exception
Traceback (most recent call last):
  File "/home/airflow/.local/lib/python3.8/site-packages/airflow/models/taskinstance.py", line 433, in _execute_task
    result = execute_callable(context=context, **execute_callable_kwargs)
  File "/home/airflow/.local/lib/python3.8/site-packages/airflow/operators/python.py", line 199, in execute
    return_value = self.execute_callable()
  File "/home/airflow/.local/lib/python3.8/site-packages/airflow/operators/python.py", line 216, in execute_callable
    return self.python_callable(*self.op_args, **self.op_kwargs)
  File "/opt/airflow/dags/tsunami_etl.py", line 44, in extract_tsunami
    with open(credentials_path, "r") as file:
FileNotFoundError: [Errno 2] No such file or directory: './credentials.json'
[2024-02-27T18:40:06.348+0000] {taskinstance.py:1138} INFO - Marking task as UP_FOR_RETRY. dag_id=tsunami_etl, task_id=extract_task, execution_date=20240101T130000, start_date=20240227T184006, end_date=20240227T184006
[2024-02-27T18:40:06.352+0000] {standard_task_runner.py:107} ERROR - Failed to execute job 41 for task extract_task ([Errno 2] No such file or directory: './credentials.json'; 1238)
[2024-02-27T18:40:06.393+0000] {local_task_job_runner.py:234} INFO - Task exited with return code 1
[2024-02-27T18:40:06.400+0000] {taskinstance.py:3281} INFO - 0 downstream tasks scheduled from follow-on schedule check
[2024-02-27T18:47:25.633+0000] {taskinstance.py:1957} INFO - Dependencies all met for dep_context=non-requeueable deps ti=<TaskInstance: tsunami_etl.extract_task scheduled__2024-01-01T13:00:00+00:00 [queued]>
[2024-02-27T18:47:25.635+0000] {taskinstance.py:1957} INFO - Dependencies all met for dep_context=requeueable deps ti=<TaskInstance: tsunami_etl.extract_task scheduled__2024-01-01T13:00:00+00:00 [queued]>
[2024-02-27T18:47:25.636+0000] {taskinstance.py:2171} INFO - Starting attempt 1 of 2
[2024-02-27T18:47:25.642+0000] {taskinstance.py:2192} INFO - Executing <Task(PythonOperator): extract_task> on 2024-01-01 13:00:00+00:00
[2024-02-27T18:47:25.645+0000] {standard_task_runner.py:60} INFO - Started process 541 to run task
[2024-02-27T18:47:25.647+0000] {standard_task_runner.py:87} INFO - Running: ['airflow', 'tasks', 'run', 'tsunami_etl', 'extract_task', 'scheduled__2024-01-01T13:00:00+00:00', '--job-id', '41', '--raw', '--subdir', 'DAGS_FOLDER/tsunami_etl.py', '--cfg-path', '/tmp/tmplu3tfbwj']
[2024-02-27T18:47:25.649+0000] {standard_task_runner.py:88} INFO - Job 41: Subtask extract_task
[2024-02-27T18:47:25.669+0000] {task_command.py:423} INFO - Running <TaskInstance: tsunami_etl.extract_task scheduled__2024-01-01T13:00:00+00:00 [running]> on host c200f435f34d
[2024-02-27T18:47:25.693+0000] {taskinstance.py:2481} INFO - Exporting env vars: AIRFLOW_CTX_DAG_OWNER='airflow' AIRFLOW_CTX_DAG_ID='tsunami_etl' AIRFLOW_CTX_TASK_ID='extract_task' AIRFLOW_CTX_EXECUTION_DATE='2024-01-01T13:00:00+00:00' AIRFLOW_CTX_TRY_NUMBER='1' AIRFLOW_CTX_DAG_RUN_ID='scheduled__2024-01-01T13:00:00+00:00'
[2024-02-27T18:47:25.694+0000] {taskinstance.py:2699} ERROR - Task failed with exception
Traceback (most recent call last):
  File "/home/airflow/.local/lib/python3.8/site-packages/airflow/models/taskinstance.py", line 433, in _execute_task
    result = execute_callable(context=context, **execute_callable_kwargs)
  File "/home/airflow/.local/lib/python3.8/site-packages/airflow/operators/python.py", line 199, in execute
    return_value = self.execute_callable()
  File "/home/airflow/.local/lib/python3.8/site-packages/airflow/operators/python.py", line 216, in execute_callable
    return self.python_callable(*self.op_args, **self.op_kwargs)
  File "/opt/airflow/dags/tsunami_etl.py", line 44, in extract_tsunami
    with open(credentials_path, "r") as file:
FileNotFoundError: [Errno 2] No such file or directory: './credentials.json'
[2024-02-27T18:47:25.696+0000] {taskinstance.py:1138} INFO - Marking task as UP_FOR_RETRY. dag_id=tsunami_etl, task_id=extract_task, execution_date=20240101T130000, start_date=20240227T184725, end_date=20240227T184725
[2024-02-27T18:47:25.699+0000] {standard_task_runner.py:107} ERROR - Failed to execute job 41 for task extract_task ([Errno 2] No such file or directory: './credentials.json'; 541)
[2024-02-27T18:47:25.704+0000] {local_task_job_runner.py:234} INFO - Task exited with return code 1
[2024-02-27T18:47:25.709+0000] {taskinstance.py:3281} INFO - 0 downstream tasks scheduled from follow-on schedule check
