[2024-02-27T13:26:09.261+0000] {taskinstance.py:1957} INFO - Dependencies all met for dep_context=non-requeueable deps ti=<TaskInstance: bbc_news_etl.extract_task scheduled__2024-01-01T13:00:00+00:00 [queued]>
[2024-02-27T13:26:09.263+0000] {taskinstance.py:1957} INFO - Dependencies all met for dep_context=requeueable deps ti=<TaskInstance: bbc_news_etl.extract_task scheduled__2024-01-01T13:00:00+00:00 [queued]>
[2024-02-27T13:26:09.263+0000] {taskinstance.py:2171} INFO - Starting attempt 1 of 2
[2024-02-27T13:26:09.269+0000] {taskinstance.py:2192} INFO - Executing <Task(PythonOperator): extract_task> on 2024-01-01 13:00:00+00:00
[2024-02-27T13:26:09.272+0000] {standard_task_runner.py:60} INFO - Started process 340 to run task
[2024-02-27T13:26:09.275+0000] {standard_task_runner.py:87} INFO - Running: ['airflow', 'tasks', 'run', 'bbc_news_etl', 'extract_task', 'scheduled__2024-01-01T13:00:00+00:00', '--job-id', '16', '--raw', '--subdir', 'DAGS_FOLDER/bbc_news_etl.py', '--cfg-path', '/tmp/tmp_8opqnkx']
[2024-02-27T13:26:09.276+0000] {standard_task_runner.py:88} INFO - Job 16: Subtask extract_task
[2024-02-27T13:26:09.305+0000] {task_command.py:423} INFO - Running <TaskInstance: bbc_news_etl.extract_task scheduled__2024-01-01T13:00:00+00:00 [running]> on host 169dadc36ff0
[2024-02-27T13:26:09.330+0000] {taskinstance.py:2481} INFO - Exporting env vars: AIRFLOW_CTX_DAG_OWNER='airflow' AIRFLOW_CTX_DAG_ID='bbc_news_etl' AIRFLOW_CTX_TASK_ID='extract_task' AIRFLOW_CTX_EXECUTION_DATE='2024-01-01T13:00:00+00:00' AIRFLOW_CTX_TRY_NUMBER='1' AIRFLOW_CTX_DAG_RUN_ID='scheduled__2024-01-01T13:00:00+00:00'
[2024-02-27T13:26:09.518+0000] {_metadata.py:139} WARNING - Compute Engine Metadata server unavailable on attempt 1 of 3. Reason: [Errno 111] Connection refused
[2024-02-27T13:26:09.519+0000] {_metadata.py:139} WARNING - Compute Engine Metadata server unavailable on attempt 2 of 3. Reason: [Errno 111] Connection refused
[2024-02-27T13:26:09.519+0000] {_metadata.py:139} WARNING - Compute Engine Metadata server unavailable on attempt 3 of 3. Reason: [Errno 111] Connection refused
[2024-02-27T13:26:09.519+0000] {_default.py:338} WARNING - Authentication failed using Compute Engine authentication due to unavailable metadata server.
[2024-02-27T13:26:09.522+0000] {taskinstance.py:2699} ERROR - Task failed with exception
Traceback (most recent call last):
  File "/home/airflow/.local/lib/python3.8/site-packages/airflow/models/taskinstance.py", line 433, in _execute_task
    result = execute_callable(context=context, **execute_callable_kwargs)
  File "/home/airflow/.local/lib/python3.8/site-packages/airflow/operators/python.py", line 199, in execute
    return_value = self.execute_callable()
  File "/home/airflow/.local/lib/python3.8/site-packages/airflow/operators/python.py", line 216, in execute_callable
    return self.python_callable(*self.op_args, **self.op_kwargs)
  File "/opt/airflow/dags/bbc_news_etl.py", line 43, in extract_bbc_news
    return pd.read_gbq(query, project_id='locator-173007', dialect='standard')
  File "/home/airflow/.local/lib/python3.8/site-packages/pandas/io/gbq.py", line 186, in read_gbq
    return pandas_gbq.read_gbq(
  File "/home/airflow/.local/lib/python3.8/site-packages/pandas_gbq/gbq.py", line 934, in read_gbq
    connector = GbqConnector(
  File "/home/airflow/.local/lib/python3.8/site-packages/pandas_gbq/gbq.py", line 318, in __init__
    self.credentials, default_project = auth.get_credentials(
  File "/home/airflow/.local/lib/python3.8/site-packages/pandas_gbq/auth.py", line 56, in get_credentials
    credentials, default_project_id = pydata_google_auth.default(
  File "/home/airflow/.local/lib/python3.8/site-packages/pydata_google_auth/auth.py", line 152, in default
    credentials = get_user_credentials(
  File "/home/airflow/.local/lib/python3.8/site-packages/pydata_google_auth/auth.py", line 362, in get_user_credentials
    credentials = _webserver.run_local_server(app_flow, **AUTH_URI_KWARGS)
  File "/home/airflow/.local/lib/python3.8/site-packages/pydata_google_auth/_webserver.py", line 89, in run_local_server
    return app_flow.run_local_server(host=LOCALHOST, port=port, **kwargs)
  File "/home/airflow/.local/lib/python3.8/site-packages/google_auth_oauthlib/flow.py", line 444, in run_local_server
    webbrowser.get(browser).open(auth_url, new=1, autoraise=True)
  File "/usr/local/lib/python3.8/webbrowser.py", line 65, in get
    raise Error("could not locate runnable browser")
webbrowser.Error: could not locate runnable browser
[2024-02-27T13:26:09.529+0000] {taskinstance.py:1138} INFO - Marking task as UP_FOR_RETRY. dag_id=bbc_news_etl, task_id=extract_task, execution_date=20240101T130000, start_date=20240227T132609, end_date=20240227T132609
[2024-02-27T13:26:09.535+0000] {standard_task_runner.py:107} ERROR - Failed to execute job 16 for task extract_task (could not locate runnable browser; 340)
[2024-02-27T13:26:09.558+0000] {local_task_job_runner.py:234} INFO - Task exited with return code 1
[2024-02-27T13:26:09.569+0000] {taskinstance.py:3281} INFO - 0 downstream tasks scheduled from follow-on schedule check
