[2024-02-27T13:48:07.953+0000] {taskinstance.py:1957} INFO - Dependencies all met for dep_context=non-requeueable deps ti=<TaskInstance: tsunami_etl.extract_task scheduled__2024-01-01T10:00:00+00:00 [queued]>
[2024-02-27T13:48:07.958+0000] {taskinstance.py:1957} INFO - Dependencies all met for dep_context=requeueable deps ti=<TaskInstance: tsunami_etl.extract_task scheduled__2024-01-01T10:00:00+00:00 [queued]>
[2024-02-27T13:48:07.958+0000] {taskinstance.py:2171} INFO - Starting attempt 1 of 2
[2024-02-27T13:48:07.967+0000] {taskinstance.py:2192} INFO - Executing <Task(PythonOperator): extract_task> on 2024-01-01 10:00:00+00:00
[2024-02-27T13:48:07.971+0000] {standard_task_runner.py:60} INFO - Started process 583 to run task
[2024-02-27T13:48:07.975+0000] {standard_task_runner.py:87} INFO - Running: ['airflow', 'tasks', 'run', 'tsunami_etl', 'extract_task', 'scheduled__2024-01-01T10:00:00+00:00', '--job-id', '29', '--raw', '--subdir', 'DAGS_FOLDER/bbc_news_etl.py', '--cfg-path', '/tmp/tmpfnvr6xin']
[2024-02-27T13:48:07.985+0000] {standard_task_runner.py:88} INFO - Job 29: Subtask extract_task
[2024-02-27T13:48:08.006+0000] {task_command.py:423} INFO - Running <TaskInstance: tsunami_etl.extract_task scheduled__2024-01-01T10:00:00+00:00 [running]> on host 169dadc36ff0
[2024-02-27T13:48:08.030+0000] {taskinstance.py:2481} INFO - Exporting env vars: AIRFLOW_CTX_DAG_OWNER='airflow' AIRFLOW_CTX_DAG_ID='tsunami_etl' AIRFLOW_CTX_TASK_ID='extract_task' AIRFLOW_CTX_EXECUTION_DATE='2024-01-01T10:00:00+00:00' AIRFLOW_CTX_TRY_NUMBER='1' AIRFLOW_CTX_DAG_RUN_ID='scheduled__2024-01-01T10:00:00+00:00'
[2024-02-27T13:48:08.177+0000] {_metadata.py:139} WARNING - Compute Engine Metadata server unavailable on attempt 1 of 3. Reason: [Errno 111] Connection refused
[2024-02-27T13:48:08.177+0000] {_metadata.py:139} WARNING - Compute Engine Metadata server unavailable on attempt 2 of 3. Reason: [Errno 111] Connection refused
[2024-02-27T13:48:08.178+0000] {_metadata.py:139} WARNING - Compute Engine Metadata server unavailable on attempt 3 of 3. Reason: [Errno 111] Connection refused
[2024-02-27T13:48:08.178+0000] {_default.py:338} WARNING - Authentication failed using Compute Engine authentication due to unavailable metadata server.
[2024-02-27T13:48:08.179+0000] {taskinstance.py:2699} ERROR - Task failed with exception
Traceback (most recent call last):
  File "/home/airflow/.local/lib/python3.8/site-packages/airflow/models/taskinstance.py", line 433, in _execute_task
    result = execute_callable(context=context, **execute_callable_kwargs)
  File "/home/airflow/.local/lib/python3.8/site-packages/airflow/operators/python.py", line 199, in execute
    return_value = self.execute_callable()
  File "/home/airflow/.local/lib/python3.8/site-packages/airflow/operators/python.py", line 216, in execute_callable
    return self.python_callable(*self.op_args, **self.op_kwargs)
  File "/opt/airflow/dags/bbc_news_etl.py", line 44, in extract_tsunami
    return pandas_gbq.read_gbq(query, project_id='locator-173007', dialect='standard')
  File "/home/airflow/.local/lib/python3.8/site-packages/pandas_gbq/gbq.py", line 934, in read_gbq
    connector = GbqConnector(
  File "/home/airflow/.local/lib/python3.8/site-packages/pandas_gbq/gbq.py", line 318, in __init__
    self.credentials, default_project = auth.get_credentials(
  File "/home/airflow/.local/lib/python3.8/site-packages/pandas_gbq/auth.py", line 56, in get_credentials
    credentials, default_project_id = pydata_google_auth.default(
  File "/home/airflow/.local/lib/python3.8/site-packages/pydata_google_auth/auth.py", line 152, in default
    credentials = get_user_credentials(
  File "/home/airflow/.local/lib/python3.8/site-packages/pydata_google_auth/auth.py", line 362, in get_user_credentials
    credentials = _webserver.run_local_server(app_flow, **AUTH_URI_KWARGS)
  File "/home/airflow/.local/lib/python3.8/site-packages/pydata_google_auth/_webserver.py", line 89, in run_local_server
    return app_flow.run_local_server(host=LOCALHOST, port=port, **kwargs)
  File "/home/airflow/.local/lib/python3.8/site-packages/google_auth_oauthlib/flow.py", line 444, in run_local_server
    webbrowser.get(browser).open(auth_url, new=1, autoraise=True)
  File "/usr/local/lib/python3.8/webbrowser.py", line 65, in get
    raise Error("could not locate runnable browser")
webbrowser.Error: could not locate runnable browser
[2024-02-27T13:48:08.183+0000] {taskinstance.py:1138} INFO - Marking task as UP_FOR_RETRY. dag_id=tsunami_etl, task_id=extract_task, execution_date=20240101T100000, start_date=20240227T134807, end_date=20240227T134808
[2024-02-27T13:48:08.189+0000] {standard_task_runner.py:107} ERROR - Failed to execute job 29 for task extract_task (could not locate runnable browser; 583)
[2024-02-27T13:48:08.212+0000] {local_task_job_runner.py:234} INFO - Task exited with return code 1
[2024-02-27T13:48:08.227+0000] {taskinstance.py:3281} INFO - 0 downstream tasks scheduled from follow-on schedule check
[2024-02-27T17:00:09.825+0000] {taskinstance.py:1957} INFO - Dependencies all met for dep_context=non-requeueable deps ti=<TaskInstance: tsunami_etl.extract_task scheduled__2024-01-01T10:00:00+00:00 [queued]>
[2024-02-27T17:00:09.828+0000] {taskinstance.py:1957} INFO - Dependencies all met for dep_context=requeueable deps ti=<TaskInstance: tsunami_etl.extract_task scheduled__2024-01-01T10:00:00+00:00 [queued]>
[2024-02-27T17:00:09.828+0000] {taskinstance.py:2171} INFO - Starting attempt 1 of 2
[2024-02-27T17:00:09.835+0000] {taskinstance.py:2192} INFO - Executing <Task(PythonOperator): extract_task> on 2024-01-01 10:00:00+00:00
[2024-02-27T17:00:09.840+0000] {standard_task_runner.py:60} INFO - Started process 356 to run task
[2024-02-27T17:00:09.843+0000] {standard_task_runner.py:87} INFO - Running: ['airflow', 'tasks', 'run', 'tsunami_etl', 'extract_task', 'scheduled__2024-01-01T10:00:00+00:00', '--job-id', '13', '--raw', '--subdir', 'DAGS_FOLDER/tsunami_etl.py', '--cfg-path', '/tmp/tmptryxnbx_']
[2024-02-27T17:00:09.845+0000] {standard_task_runner.py:88} INFO - Job 13: Subtask extract_task
[2024-02-27T17:00:09.865+0000] {task_command.py:423} INFO - Running <TaskInstance: tsunami_etl.extract_task scheduled__2024-01-01T10:00:00+00:00 [running]> on host 45e004960ef9
[2024-02-27T17:00:09.889+0000] {taskinstance.py:2481} INFO - Exporting env vars: AIRFLOW_CTX_DAG_OWNER='airflow' AIRFLOW_CTX_DAG_ID='tsunami_etl' AIRFLOW_CTX_TASK_ID='extract_task' AIRFLOW_CTX_EXECUTION_DATE='2024-01-01T10:00:00+00:00' AIRFLOW_CTX_TRY_NUMBER='1' AIRFLOW_CTX_DAG_RUN_ID='scheduled__2024-01-01T10:00:00+00:00'
[2024-02-27T17:00:09.890+0000] {taskinstance.py:2699} ERROR - Task failed with exception
Traceback (most recent call last):
  File "/home/airflow/.local/lib/python3.8/site-packages/airflow/models/taskinstance.py", line 433, in _execute_task
    result = execute_callable(context=context, **execute_callable_kwargs)
  File "/home/airflow/.local/lib/python3.8/site-packages/airflow/operators/python.py", line 199, in execute
    return_value = self.execute_callable()
  File "/home/airflow/.local/lib/python3.8/site-packages/airflow/operators/python.py", line 216, in execute_callable
    return self.python_callable(*self.op_args, **self.op_kwargs)
  File "/opt/airflow/dags/tsunami_etl.py", line 46, in extract_tsunami
    GCPCredentials = service_account.Credentials.from_service_account_file(f"../auth/json/{CREDENTIALS_FILE}")
  File "/home/airflow/.local/lib/python3.8/site-packages/google/oauth2/service_account.py", line 257, in from_service_account_file
    info, signer = _service_account_info.from_filename(
  File "/home/airflow/.local/lib/python3.8/site-packages/google/auth/_service_account_info.py", line 78, in from_filename
    with io.open(filename, "r", encoding="utf-8") as json_file:
FileNotFoundError: [Errno 2] No such file or directory: '../auth/json/None'
[2024-02-27T17:00:09.892+0000] {taskinstance.py:1138} INFO - Marking task as UP_FOR_RETRY. dag_id=tsunami_etl, task_id=extract_task, execution_date=20240101T100000, start_date=20240227T170009, end_date=20240227T170009
[2024-02-27T17:00:09.896+0000] {standard_task_runner.py:107} ERROR - Failed to execute job 13 for task extract_task ([Errno 2] No such file or directory: '../auth/json/None'; 356)
[2024-02-27T17:00:09.942+0000] {local_task_job_runner.py:234} INFO - Task exited with return code 1
[2024-02-27T17:00:09.950+0000] {taskinstance.py:3281} INFO - 0 downstream tasks scheduled from follow-on schedule check
[2024-02-27T17:04:27.171+0000] {taskinstance.py:1957} INFO - Dependencies all met for dep_context=non-requeueable deps ti=<TaskInstance: tsunami_etl.extract_task scheduled__2024-01-01T10:00:00+00:00 [queued]>
[2024-02-27T17:04:27.173+0000] {taskinstance.py:1957} INFO - Dependencies all met for dep_context=requeueable deps ti=<TaskInstance: tsunami_etl.extract_task scheduled__2024-01-01T10:00:00+00:00 [queued]>
[2024-02-27T17:04:27.173+0000] {taskinstance.py:2171} INFO - Starting attempt 1 of 2
[2024-02-27T17:04:27.179+0000] {taskinstance.py:2192} INFO - Executing <Task(PythonOperator): extract_task> on 2024-01-01 10:00:00+00:00
[2024-02-27T17:04:27.182+0000] {standard_task_runner.py:60} INFO - Started process 567 to run task
[2024-02-27T17:04:27.184+0000] {standard_task_runner.py:87} INFO - Running: ['airflow', 'tasks', 'run', 'tsunami_etl', 'extract_task', 'scheduled__2024-01-01T10:00:00+00:00', '--job-id', '28', '--raw', '--subdir', 'DAGS_FOLDER/tsunami_etl.py', '--cfg-path', '/tmp/tmp4rl26fb0']
[2024-02-27T17:04:27.185+0000] {standard_task_runner.py:88} INFO - Job 28: Subtask extract_task
[2024-02-27T17:04:27.201+0000] {task_command.py:423} INFO - Running <TaskInstance: tsunami_etl.extract_task scheduled__2024-01-01T10:00:00+00:00 [running]> on host 45e004960ef9
[2024-02-27T17:04:27.223+0000] {taskinstance.py:2481} INFO - Exporting env vars: AIRFLOW_CTX_DAG_OWNER='airflow' AIRFLOW_CTX_DAG_ID='tsunami_etl' AIRFLOW_CTX_TASK_ID='extract_task' AIRFLOW_CTX_EXECUTION_DATE='2024-01-01T10:00:00+00:00' AIRFLOW_CTX_TRY_NUMBER='1' AIRFLOW_CTX_DAG_RUN_ID='scheduled__2024-01-01T10:00:00+00:00'
[2024-02-27T17:04:27.223+0000] {taskinstance.py:2699} ERROR - Task failed with exception
Traceback (most recent call last):
  File "/home/airflow/.local/lib/python3.8/site-packages/airflow/models/taskinstance.py", line 433, in _execute_task
    result = execute_callable(context=context, **execute_callable_kwargs)
  File "/home/airflow/.local/lib/python3.8/site-packages/airflow/operators/python.py", line 199, in execute
    return_value = self.execute_callable()
  File "/home/airflow/.local/lib/python3.8/site-packages/airflow/operators/python.py", line 216, in execute_callable
    return self.python_callable(*self.op_args, **self.op_kwargs)
  File "/opt/airflow/dags/tsunami_etl.py", line 42, in extract_tsunami
    GCPCredentials = service_account.Credentials.from_service_account_file(f"../auth/json/{CREDENTIALS_FILE}")
  File "/home/airflow/.local/lib/python3.8/site-packages/google/oauth2/service_account.py", line 257, in from_service_account_file
    info, signer = _service_account_info.from_filename(
  File "/home/airflow/.local/lib/python3.8/site-packages/google/auth/_service_account_info.py", line 78, in from_filename
    with io.open(filename, "r", encoding="utf-8") as json_file:
FileNotFoundError: [Errno 2] No such file or directory: '../auth/json/None'
[2024-02-27T17:04:27.225+0000] {taskinstance.py:1138} INFO - Marking task as UP_FOR_RETRY. dag_id=tsunami_etl, task_id=extract_task, execution_date=20240101T100000, start_date=20240227T170427, end_date=20240227T170427
[2024-02-27T17:04:27.229+0000] {standard_task_runner.py:107} ERROR - Failed to execute job 28 for task extract_task ([Errno 2] No such file or directory: '../auth/json/None'; 567)
[2024-02-27T17:04:27.238+0000] {local_task_job_runner.py:234} INFO - Task exited with return code 1
[2024-02-27T17:04:27.245+0000] {taskinstance.py:3281} INFO - 0 downstream tasks scheduled from follow-on schedule check
[2024-02-27T17:06:31.420+0000] {taskinstance.py:1957} INFO - Dependencies all met for dep_context=non-requeueable deps ti=<TaskInstance: tsunami_etl.extract_task scheduled__2024-01-01T10:00:00+00:00 [queued]>
[2024-02-27T17:06:31.423+0000] {taskinstance.py:1957} INFO - Dependencies all met for dep_context=requeueable deps ti=<TaskInstance: tsunami_etl.extract_task scheduled__2024-01-01T10:00:00+00:00 [queued]>
[2024-02-27T17:06:31.423+0000] {taskinstance.py:2171} INFO - Starting attempt 1 of 2
[2024-02-27T17:06:31.429+0000] {taskinstance.py:2192} INFO - Executing <Task(PythonOperator): extract_task> on 2024-01-01 10:00:00+00:00
[2024-02-27T17:06:31.431+0000] {standard_task_runner.py:60} INFO - Started process 759 to run task
[2024-02-27T17:06:31.434+0000] {standard_task_runner.py:87} INFO - Running: ['airflow', 'tasks', 'run', 'tsunami_etl', 'extract_task', 'scheduled__2024-01-01T10:00:00+00:00', '--job-id', '44', '--raw', '--subdir', 'DAGS_FOLDER/tsunami_etl.py', '--cfg-path', '/tmp/tmpe8udey2b']
[2024-02-27T17:06:31.435+0000] {standard_task_runner.py:88} INFO - Job 44: Subtask extract_task
[2024-02-27T17:06:31.452+0000] {task_command.py:423} INFO - Running <TaskInstance: tsunami_etl.extract_task scheduled__2024-01-01T10:00:00+00:00 [running]> on host 45e004960ef9
[2024-02-27T17:06:31.488+0000] {taskinstance.py:2481} INFO - Exporting env vars: AIRFLOW_CTX_DAG_OWNER='airflow' AIRFLOW_CTX_DAG_ID='tsunami_etl' AIRFLOW_CTX_TASK_ID='extract_task' AIRFLOW_CTX_EXECUTION_DATE='2024-01-01T10:00:00+00:00' AIRFLOW_CTX_TRY_NUMBER='1' AIRFLOW_CTX_DAG_RUN_ID='scheduled__2024-01-01T10:00:00+00:00'
[2024-02-27T17:06:31.489+0000] {taskinstance.py:2699} ERROR - Task failed with exception
Traceback (most recent call last):
  File "/home/airflow/.local/lib/python3.8/site-packages/airflow/models/taskinstance.py", line 433, in _execute_task
    result = execute_callable(context=context, **execute_callable_kwargs)
  File "/home/airflow/.local/lib/python3.8/site-packages/airflow/operators/python.py", line 199, in execute
    return_value = self.execute_callable()
  File "/home/airflow/.local/lib/python3.8/site-packages/airflow/operators/python.py", line 216, in execute_callable
    return self.python_callable(*self.op_args, **self.op_kwargs)
  File "/opt/airflow/dags/tsunami_etl.py", line 42, in extract_tsunami
    GCPCredentials = service_account.Credentials.from_service_account_file(f"../auth/json/credentials.json")
  File "/home/airflow/.local/lib/python3.8/site-packages/google/oauth2/service_account.py", line 257, in from_service_account_file
    info, signer = _service_account_info.from_filename(
  File "/home/airflow/.local/lib/python3.8/site-packages/google/auth/_service_account_info.py", line 78, in from_filename
    with io.open(filename, "r", encoding="utf-8") as json_file:
FileNotFoundError: [Errno 2] No such file or directory: '../auth/json/credentials.json'
[2024-02-27T17:06:31.491+0000] {taskinstance.py:1138} INFO - Marking task as UP_FOR_RETRY. dag_id=tsunami_etl, task_id=extract_task, execution_date=20240101T100000, start_date=20240227T170631, end_date=20240227T170631
[2024-02-27T17:06:31.496+0000] {standard_task_runner.py:107} ERROR - Failed to execute job 44 for task extract_task ([Errno 2] No such file or directory: '../auth/json/credentials.json'; 759)
[2024-02-27T17:06:31.534+0000] {local_task_job_runner.py:234} INFO - Task exited with return code 1
[2024-02-27T17:06:31.543+0000] {taskinstance.py:3281} INFO - 0 downstream tasks scheduled from follow-on schedule check
[2024-02-27T17:09:58.587+0000] {taskinstance.py:1957} INFO - Dependencies all met for dep_context=non-requeueable deps ti=<TaskInstance: tsunami_etl.extract_task scheduled__2024-01-01T10:00:00+00:00 [queued]>
[2024-02-27T17:09:58.590+0000] {taskinstance.py:1957} INFO - Dependencies all met for dep_context=requeueable deps ti=<TaskInstance: tsunami_etl.extract_task scheduled__2024-01-01T10:00:00+00:00 [queued]>
[2024-02-27T17:09:58.590+0000] {taskinstance.py:2171} INFO - Starting attempt 1 of 2
[2024-02-27T17:09:58.595+0000] {taskinstance.py:2192} INFO - Executing <Task(PythonOperator): extract_task> on 2024-01-01 10:00:00+00:00
[2024-02-27T17:09:58.606+0000] {standard_task_runner.py:60} INFO - Started process 958 to run task
[2024-02-27T17:09:58.608+0000] {standard_task_runner.py:87} INFO - Running: ['airflow', 'tasks', 'run', 'tsunami_etl', 'extract_task', 'scheduled__2024-01-01T10:00:00+00:00', '--job-id', '12', '--raw', '--subdir', 'DAGS_FOLDER/tsunami_etl.py', '--cfg-path', '/tmp/tmpk5pfhnct']
[2024-02-27T17:09:58.610+0000] {standard_task_runner.py:88} INFO - Job 12: Subtask extract_task
[2024-02-27T17:09:58.642+0000] {task_command.py:423} INFO - Running <TaskInstance: tsunami_etl.extract_task scheduled__2024-01-01T10:00:00+00:00 [running]> on host 45e004960ef9
[2024-02-27T17:09:58.667+0000] {taskinstance.py:2481} INFO - Exporting env vars: AIRFLOW_CTX_DAG_OWNER='airflow' AIRFLOW_CTX_DAG_ID='tsunami_etl' AIRFLOW_CTX_TASK_ID='extract_task' AIRFLOW_CTX_EXECUTION_DATE='2024-01-01T10:00:00+00:00' AIRFLOW_CTX_TRY_NUMBER='1' AIRFLOW_CTX_DAG_RUN_ID='scheduled__2024-01-01T10:00:00+00:00'
[2024-02-27T17:09:58.668+0000] {taskinstance.py:2699} ERROR - Task failed with exception
Traceback (most recent call last):
  File "/home/airflow/.local/lib/python3.8/site-packages/airflow/models/taskinstance.py", line 433, in _execute_task
    result = execute_callable(context=context, **execute_callable_kwargs)
  File "/home/airflow/.local/lib/python3.8/site-packages/airflow/operators/python.py", line 199, in execute
    return_value = self.execute_callable()
  File "/home/airflow/.local/lib/python3.8/site-packages/airflow/operators/python.py", line 216, in execute_callable
    return self.python_callable(*self.op_args, **self.op_kwargs)
  File "/opt/airflow/dags/tsunami_etl.py", line 41, in extract_tsunami
    GCPCredentials = service_account.Credentials.from_service_account_file("credentials.json")
  File "/home/airflow/.local/lib/python3.8/site-packages/google/oauth2/service_account.py", line 257, in from_service_account_file
    info, signer = _service_account_info.from_filename(
  File "/home/airflow/.local/lib/python3.8/site-packages/google/auth/_service_account_info.py", line 78, in from_filename
    with io.open(filename, "r", encoding="utf-8") as json_file:
FileNotFoundError: [Errno 2] No such file or directory: 'credentials.json'
[2024-02-27T17:09:58.671+0000] {taskinstance.py:1138} INFO - Marking task as UP_FOR_RETRY. dag_id=tsunami_etl, task_id=extract_task, execution_date=20240101T100000, start_date=20240227T170958, end_date=20240227T170958
[2024-02-27T17:09:58.675+0000] {standard_task_runner.py:107} ERROR - Failed to execute job 12 for task extract_task ([Errno 2] No such file or directory: 'credentials.json'; 958)
[2024-02-27T17:09:58.706+0000] {local_task_job_runner.py:234} INFO - Task exited with return code 1
[2024-02-27T17:09:58.717+0000] {taskinstance.py:3281} INFO - 0 downstream tasks scheduled from follow-on schedule check
[2024-02-27T18:09:52.757+0000] {taskinstance.py:1957} INFO - Dependencies all met for dep_context=non-requeueable deps ti=<TaskInstance: tsunami_etl.extract_task scheduled__2024-01-01T10:00:00+00:00 [queued]>
[2024-02-27T18:09:52.759+0000] {taskinstance.py:1957} INFO - Dependencies all met for dep_context=requeueable deps ti=<TaskInstance: tsunami_etl.extract_task scheduled__2024-01-01T10:00:00+00:00 [queued]>
[2024-02-27T18:09:52.759+0000] {taskinstance.py:2171} INFO - Starting attempt 1 of 2
[2024-02-27T18:09:52.765+0000] {taskinstance.py:2192} INFO - Executing <Task(PythonOperator): extract_task> on 2024-01-01 10:00:00+00:00
[2024-02-27T18:09:52.768+0000] {standard_task_runner.py:60} INFO - Started process 434 to run task
[2024-02-27T18:09:52.771+0000] {standard_task_runner.py:87} INFO - Running: ['airflow', 'tasks', 'run', 'tsunami_etl', 'extract_task', 'scheduled__2024-01-01T10:00:00+00:00', '--job-id', '32', '--raw', '--subdir', 'DAGS_FOLDER/tsunami_etl.py', '--cfg-path', '/tmp/tmpdeoknpae']
[2024-02-27T18:09:52.773+0000] {standard_task_runner.py:88} INFO - Job 32: Subtask extract_task
[2024-02-27T18:09:52.789+0000] {task_command.py:423} INFO - Running <TaskInstance: tsunami_etl.extract_task scheduled__2024-01-01T10:00:00+00:00 [running]> on host cf5ca63d0f74
[2024-02-27T18:09:52.812+0000] {taskinstance.py:2481} INFO - Exporting env vars: AIRFLOW_CTX_DAG_OWNER='airflow' AIRFLOW_CTX_DAG_ID='tsunami_etl' AIRFLOW_CTX_TASK_ID='extract_task' AIRFLOW_CTX_EXECUTION_DATE='2024-01-01T10:00:00+00:00' AIRFLOW_CTX_TRY_NUMBER='1' AIRFLOW_CTX_DAG_RUN_ID='scheduled__2024-01-01T10:00:00+00:00'
[2024-02-27T18:09:52.813+0000] {taskinstance.py:2699} ERROR - Task failed with exception
Traceback (most recent call last):
  File "/home/airflow/.local/lib/python3.8/site-packages/airflow/models/taskinstance.py", line 433, in _execute_task
    result = execute_callable(context=context, **execute_callable_kwargs)
  File "/home/airflow/.local/lib/python3.8/site-packages/airflow/operators/python.py", line 199, in execute
    return_value = self.execute_callable()
  File "/home/airflow/.local/lib/python3.8/site-packages/airflow/operators/python.py", line 216, in execute_callable
    return self.python_callable(*self.op_args, **self.op_kwargs)
  File "/opt/airflow/dags/tsunami_etl.py", line 42, in extract_tsunami
    GCPCredentials = service_account.Credentials.from_service_account_file(credentials_path)
  File "/home/airflow/.local/lib/python3.8/site-packages/google/oauth2/service_account.py", line 257, in from_service_account_file
    info, signer = _service_account_info.from_filename(
  File "/home/airflow/.local/lib/python3.8/site-packages/google/auth/_service_account_info.py", line 78, in from_filename
    with io.open(filename, "r", encoding="utf-8") as json_file:
FileNotFoundError: [Errno 2] No such file or directory: './credentials.json'
[2024-02-27T18:09:52.815+0000] {taskinstance.py:1138} INFO - Marking task as UP_FOR_RETRY. dag_id=tsunami_etl, task_id=extract_task, execution_date=20240101T100000, start_date=20240227T180952, end_date=20240227T180952
[2024-02-27T18:09:52.819+0000] {standard_task_runner.py:107} ERROR - Failed to execute job 32 for task extract_task ([Errno 2] No such file or directory: './credentials.json'; 434)
[2024-02-27T18:09:52.828+0000] {local_task_job_runner.py:234} INFO - Task exited with return code 1
[2024-02-27T18:09:52.834+0000] {taskinstance.py:3281} INFO - 0 downstream tasks scheduled from follow-on schedule check
[2024-02-27T18:19:54.131+0000] {taskinstance.py:1957} INFO - Dependencies all met for dep_context=non-requeueable deps ti=<TaskInstance: tsunami_etl.extract_task scheduled__2024-01-01T10:00:00+00:00 [queued]>
[2024-02-27T18:19:54.133+0000] {taskinstance.py:1957} INFO - Dependencies all met for dep_context=requeueable deps ti=<TaskInstance: tsunami_etl.extract_task scheduled__2024-01-01T10:00:00+00:00 [queued]>
[2024-02-27T18:19:54.134+0000] {taskinstance.py:2171} INFO - Starting attempt 1 of 2
[2024-02-27T18:19:54.139+0000] {taskinstance.py:2192} INFO - Executing <Task(PythonOperator): extract_task> on 2024-01-01 10:00:00+00:00
[2024-02-27T18:19:54.143+0000] {standard_task_runner.py:60} INFO - Started process 432 to run task
[2024-02-27T18:19:54.146+0000] {standard_task_runner.py:87} INFO - Running: ['airflow', 'tasks', 'run', 'tsunami_etl', 'extract_task', 'scheduled__2024-01-01T10:00:00+00:00', '--job-id', '32', '--raw', '--subdir', 'DAGS_FOLDER/tsunami_etl.py', '--cfg-path', '/tmp/tmprjig6of5']
[2024-02-27T18:19:54.147+0000] {standard_task_runner.py:88} INFO - Job 32: Subtask extract_task
[2024-02-27T18:19:54.175+0000] {task_command.py:423} INFO - Running <TaskInstance: tsunami_etl.extract_task scheduled__2024-01-01T10:00:00+00:00 [running]> on host 38ece35a2749
[2024-02-27T18:19:54.199+0000] {taskinstance.py:2481} INFO - Exporting env vars: AIRFLOW_CTX_DAG_OWNER='airflow' AIRFLOW_CTX_DAG_ID='tsunami_etl' AIRFLOW_CTX_TASK_ID='extract_task' AIRFLOW_CTX_EXECUTION_DATE='2024-01-01T10:00:00+00:00' AIRFLOW_CTX_TRY_NUMBER='1' AIRFLOW_CTX_DAG_RUN_ID='scheduled__2024-01-01T10:00:00+00:00'
[2024-02-27T18:19:54.200+0000] {taskinstance.py:2699} ERROR - Task failed with exception
Traceback (most recent call last):
  File "/home/airflow/.local/lib/python3.8/site-packages/airflow/models/taskinstance.py", line 433, in _execute_task
    result = execute_callable(context=context, **execute_callable_kwargs)
  File "/home/airflow/.local/lib/python3.8/site-packages/airflow/operators/python.py", line 199, in execute
    return_value = self.execute_callable()
  File "/home/airflow/.local/lib/python3.8/site-packages/airflow/operators/python.py", line 216, in execute_callable
    return self.python_callable(*self.op_args, **self.op_kwargs)
  File "/opt/airflow/dags/tsunami_etl.py", line 44, in extract_tsunami
    GCPCredentials = service_account.Credentials.from_service_account_info(json.loads(credentials_path))
  File "/usr/local/lib/python3.8/json/__init__.py", line 357, in loads
    return _default_decoder.decode(s)
  File "/usr/local/lib/python3.8/json/decoder.py", line 337, in decode
    obj, end = self.raw_decode(s, idx=_w(s, 0).end())
  File "/usr/local/lib/python3.8/json/decoder.py", line 355, in raw_decode
    raise JSONDecodeError("Expecting value", s, err.value) from None
json.decoder.JSONDecodeError: Expecting value: line 1 column 1 (char 0)
[2024-02-27T18:19:54.202+0000] {taskinstance.py:1138} INFO - Marking task as UP_FOR_RETRY. dag_id=tsunami_etl, task_id=extract_task, execution_date=20240101T100000, start_date=20240227T181954, end_date=20240227T181954
[2024-02-27T18:19:54.206+0000] {standard_task_runner.py:107} ERROR - Failed to execute job 32 for task extract_task (Expecting value: line 1 column 1 (char 0); 432)
[2024-02-27T18:19:54.247+0000] {local_task_job_runner.py:234} INFO - Task exited with return code 1
[2024-02-27T18:19:54.253+0000] {taskinstance.py:3281} INFO - 0 downstream tasks scheduled from follow-on schedule check
[2024-02-27T18:39:51.930+0000] {taskinstance.py:1957} INFO - Dependencies all met for dep_context=non-requeueable deps ti=<TaskInstance: tsunami_etl.extract_task scheduled__2024-01-01T10:00:00+00:00 [queued]>
[2024-02-27T18:39:51.933+0000] {taskinstance.py:1957} INFO - Dependencies all met for dep_context=requeueable deps ti=<TaskInstance: tsunami_etl.extract_task scheduled__2024-01-01T10:00:00+00:00 [queued]>
[2024-02-27T18:39:51.933+0000] {taskinstance.py:2171} INFO - Starting attempt 1 of 2
[2024-02-27T18:39:51.938+0000] {taskinstance.py:2192} INFO - Executing <Task(PythonOperator): extract_task> on 2024-01-01 10:00:00+00:00
[2024-02-27T18:39:51.940+0000] {standard_task_runner.py:60} INFO - Started process 1137 to run task
[2024-02-27T18:39:51.942+0000] {standard_task_runner.py:87} INFO - Running: ['airflow', 'tasks', 'run', 'tsunami_etl', 'extract_task', 'scheduled__2024-01-01T10:00:00+00:00', '--job-id', '32', '--raw', '--subdir', 'DAGS_FOLDER/tsunami_etl.py', '--cfg-path', '/tmp/tmpno4edmf6']
[2024-02-27T18:39:51.944+0000] {standard_task_runner.py:88} INFO - Job 32: Subtask extract_task
[2024-02-27T18:39:51.959+0000] {task_command.py:423} INFO - Running <TaskInstance: tsunami_etl.extract_task scheduled__2024-01-01T10:00:00+00:00 [running]> on host f8b0167ca209
[2024-02-27T18:39:51.981+0000] {taskinstance.py:2481} INFO - Exporting env vars: AIRFLOW_CTX_DAG_OWNER='airflow' AIRFLOW_CTX_DAG_ID='tsunami_etl' AIRFLOW_CTX_TASK_ID='extract_task' AIRFLOW_CTX_EXECUTION_DATE='2024-01-01T10:00:00+00:00' AIRFLOW_CTX_TRY_NUMBER='1' AIRFLOW_CTX_DAG_RUN_ID='scheduled__2024-01-01T10:00:00+00:00'
[2024-02-27T18:39:51.982+0000] {taskinstance.py:2699} ERROR - Task failed with exception
Traceback (most recent call last):
  File "/home/airflow/.local/lib/python3.8/site-packages/airflow/models/taskinstance.py", line 433, in _execute_task
    result = execute_callable(context=context, **execute_callable_kwargs)
  File "/home/airflow/.local/lib/python3.8/site-packages/airflow/operators/python.py", line 199, in execute
    return_value = self.execute_callable()
  File "/home/airflow/.local/lib/python3.8/site-packages/airflow/operators/python.py", line 216, in execute_callable
    return self.python_callable(*self.op_args, **self.op_kwargs)
  File "/opt/airflow/dags/tsunami_etl.py", line 44, in extract_tsunami
    with open(credentials_path, "r") as file:
FileNotFoundError: [Errno 2] No such file or directory: './credentials.json'
[2024-02-27T18:39:51.983+0000] {taskinstance.py:1138} INFO - Marking task as UP_FOR_RETRY. dag_id=tsunami_etl, task_id=extract_task, execution_date=20240101T100000, start_date=20240227T183951, end_date=20240227T183951
[2024-02-27T18:39:51.987+0000] {standard_task_runner.py:107} ERROR - Failed to execute job 32 for task extract_task ([Errno 2] No such file or directory: './credentials.json'; 1137)
[2024-02-27T18:39:51.999+0000] {local_task_job_runner.py:234} INFO - Task exited with return code 1
[2024-02-27T18:39:52.005+0000] {taskinstance.py:3281} INFO - 0 downstream tasks scheduled from follow-on schedule check
[2024-02-27T18:47:10.571+0000] {taskinstance.py:1957} INFO - Dependencies all met for dep_context=non-requeueable deps ti=<TaskInstance: tsunami_etl.extract_task scheduled__2024-01-01T10:00:00+00:00 [queued]>
[2024-02-27T18:47:10.575+0000] {taskinstance.py:1957} INFO - Dependencies all met for dep_context=requeueable deps ti=<TaskInstance: tsunami_etl.extract_task scheduled__2024-01-01T10:00:00+00:00 [queued]>
[2024-02-27T18:47:10.575+0000] {taskinstance.py:2171} INFO - Starting attempt 1 of 2
[2024-02-27T18:47:10.582+0000] {taskinstance.py:2192} INFO - Executing <Task(PythonOperator): extract_task> on 2024-01-01 10:00:00+00:00
[2024-02-27T18:47:10.589+0000] {standard_task_runner.py:60} INFO - Started process 442 to run task
[2024-02-27T18:47:10.592+0000] {standard_task_runner.py:87} INFO - Running: ['airflow', 'tasks', 'run', 'tsunami_etl', 'extract_task', 'scheduled__2024-01-01T10:00:00+00:00', '--job-id', '32', '--raw', '--subdir', 'DAGS_FOLDER/tsunami_etl.py', '--cfg-path', '/tmp/tmpvdsw1aio']
[2024-02-27T18:47:10.594+0000] {standard_task_runner.py:88} INFO - Job 32: Subtask extract_task
[2024-02-27T18:47:10.640+0000] {task_command.py:423} INFO - Running <TaskInstance: tsunami_etl.extract_task scheduled__2024-01-01T10:00:00+00:00 [running]> on host c200f435f34d
[2024-02-27T18:47:10.677+0000] {taskinstance.py:2481} INFO - Exporting env vars: AIRFLOW_CTX_DAG_OWNER='airflow' AIRFLOW_CTX_DAG_ID='tsunami_etl' AIRFLOW_CTX_TASK_ID='extract_task' AIRFLOW_CTX_EXECUTION_DATE='2024-01-01T10:00:00+00:00' AIRFLOW_CTX_TRY_NUMBER='1' AIRFLOW_CTX_DAG_RUN_ID='scheduled__2024-01-01T10:00:00+00:00'
[2024-02-27T18:47:10.678+0000] {taskinstance.py:2699} ERROR - Task failed with exception
Traceback (most recent call last):
  File "/home/airflow/.local/lib/python3.8/site-packages/airflow/models/taskinstance.py", line 433, in _execute_task
    result = execute_callable(context=context, **execute_callable_kwargs)
  File "/home/airflow/.local/lib/python3.8/site-packages/airflow/operators/python.py", line 199, in execute
    return_value = self.execute_callable()
  File "/home/airflow/.local/lib/python3.8/site-packages/airflow/operators/python.py", line 216, in execute_callable
    return self.python_callable(*self.op_args, **self.op_kwargs)
  File "/opt/airflow/dags/tsunami_etl.py", line 44, in extract_tsunami
    with open(credentials_path, "r") as file:
FileNotFoundError: [Errno 2] No such file or directory: './credentials.json'
[2024-02-27T18:47:10.681+0000] {taskinstance.py:1138} INFO - Marking task as UP_FOR_RETRY. dag_id=tsunami_etl, task_id=extract_task, execution_date=20240101T100000, start_date=20240227T184710, end_date=20240227T184710
[2024-02-27T18:47:10.686+0000] {standard_task_runner.py:107} ERROR - Failed to execute job 32 for task extract_task ([Errno 2] No such file or directory: './credentials.json'; 442)
[2024-02-27T18:47:10.737+0000] {local_task_job_runner.py:234} INFO - Task exited with return code 1
[2024-02-27T18:47:10.743+0000] {taskinstance.py:3281} INFO - 0 downstream tasks scheduled from follow-on schedule check
