[2024-02-27T13:48:12.161+0000] {taskinstance.py:1957} INFO - Dependencies all met for dep_context=non-requeueable deps ti=<TaskInstance: tsunami_etl.extract_task scheduled__2024-01-01T12:00:00+00:00 [queued]>
[2024-02-27T13:48:12.164+0000] {taskinstance.py:1957} INFO - Dependencies all met for dep_context=requeueable deps ti=<TaskInstance: tsunami_etl.extract_task scheduled__2024-01-01T12:00:00+00:00 [queued]>
[2024-02-27T13:48:12.164+0000] {taskinstance.py:2171} INFO - Starting attempt 1 of 2
[2024-02-27T13:48:12.171+0000] {taskinstance.py:2192} INFO - Executing <Task(PythonOperator): extract_task> on 2024-01-01 12:00:00+00:00
[2024-02-27T13:48:12.176+0000] {standard_task_runner.py:60} INFO - Started process 605 to run task
[2024-02-27T13:48:12.179+0000] {standard_task_runner.py:87} INFO - Running: ['airflow', 'tasks', 'run', 'tsunami_etl', 'extract_task', 'scheduled__2024-01-01T12:00:00+00:00', '--job-id', '31', '--raw', '--subdir', 'DAGS_FOLDER/bbc_news_etl.py', '--cfg-path', '/tmp/tmp163ej736']
[2024-02-27T13:48:12.180+0000] {standard_task_runner.py:88} INFO - Job 31: Subtask extract_task
[2024-02-27T13:48:12.209+0000] {task_command.py:423} INFO - Running <TaskInstance: tsunami_etl.extract_task scheduled__2024-01-01T12:00:00+00:00 [running]> on host 169dadc36ff0
[2024-02-27T13:48:12.241+0000] {taskinstance.py:2481} INFO - Exporting env vars: AIRFLOW_CTX_DAG_OWNER='airflow' AIRFLOW_CTX_DAG_ID='tsunami_etl' AIRFLOW_CTX_TASK_ID='extract_task' AIRFLOW_CTX_EXECUTION_DATE='2024-01-01T12:00:00+00:00' AIRFLOW_CTX_TRY_NUMBER='1' AIRFLOW_CTX_DAG_RUN_ID='scheduled__2024-01-01T12:00:00+00:00'
[2024-02-27T13:48:12.436+0000] {_metadata.py:139} WARNING - Compute Engine Metadata server unavailable on attempt 1 of 3. Reason: [Errno 111] Connection refused
[2024-02-27T13:48:12.437+0000] {_metadata.py:139} WARNING - Compute Engine Metadata server unavailable on attempt 2 of 3. Reason: [Errno 111] Connection refused
[2024-02-27T13:48:12.438+0000] {_metadata.py:139} WARNING - Compute Engine Metadata server unavailable on attempt 3 of 3. Reason: [Errno 111] Connection refused
[2024-02-27T13:48:12.438+0000] {_default.py:338} WARNING - Authentication failed using Compute Engine authentication due to unavailable metadata server.
[2024-02-27T13:48:12.439+0000] {taskinstance.py:2699} ERROR - Task failed with exception
Traceback (most recent call last):
  File "/home/airflow/.local/lib/python3.8/site-packages/airflow/models/taskinstance.py", line 433, in _execute_task
    result = execute_callable(context=context, **execute_callable_kwargs)
  File "/home/airflow/.local/lib/python3.8/site-packages/airflow/operators/python.py", line 199, in execute
    return_value = self.execute_callable()
  File "/home/airflow/.local/lib/python3.8/site-packages/airflow/operators/python.py", line 216, in execute_callable
    return self.python_callable(*self.op_args, **self.op_kwargs)
  File "/opt/airflow/dags/bbc_news_etl.py", line 44, in extract_tsunami
    return pandas_gbq.read_gbq(query, project_id='locator-173007', dialect='standard')
  File "/home/airflow/.local/lib/python3.8/site-packages/pandas_gbq/gbq.py", line 934, in read_gbq
    connector = GbqConnector(
  File "/home/airflow/.local/lib/python3.8/site-packages/pandas_gbq/gbq.py", line 318, in __init__
    self.credentials, default_project = auth.get_credentials(
  File "/home/airflow/.local/lib/python3.8/site-packages/pandas_gbq/auth.py", line 56, in get_credentials
    credentials, default_project_id = pydata_google_auth.default(
  File "/home/airflow/.local/lib/python3.8/site-packages/pydata_google_auth/auth.py", line 152, in default
    credentials = get_user_credentials(
  File "/home/airflow/.local/lib/python3.8/site-packages/pydata_google_auth/auth.py", line 362, in get_user_credentials
    credentials = _webserver.run_local_server(app_flow, **AUTH_URI_KWARGS)
  File "/home/airflow/.local/lib/python3.8/site-packages/pydata_google_auth/_webserver.py", line 89, in run_local_server
    return app_flow.run_local_server(host=LOCALHOST, port=port, **kwargs)
  File "/home/airflow/.local/lib/python3.8/site-packages/google_auth_oauthlib/flow.py", line 444, in run_local_server
    webbrowser.get(browser).open(auth_url, new=1, autoraise=True)
  File "/usr/local/lib/python3.8/webbrowser.py", line 65, in get
    raise Error("could not locate runnable browser")
webbrowser.Error: could not locate runnable browser
[2024-02-27T13:48:12.443+0000] {taskinstance.py:1138} INFO - Marking task as UP_FOR_RETRY. dag_id=tsunami_etl, task_id=extract_task, execution_date=20240101T120000, start_date=20240227T134812, end_date=20240227T134812
[2024-02-27T13:48:12.448+0000] {standard_task_runner.py:107} ERROR - Failed to execute job 31 for task extract_task (could not locate runnable browser; 605)
[2024-02-27T13:48:12.456+0000] {local_task_job_runner.py:234} INFO - Task exited with return code 1
[2024-02-27T13:48:12.465+0000] {taskinstance.py:3281} INFO - 0 downstream tasks scheduled from follow-on schedule check
[2024-02-27T17:00:13.548+0000] {taskinstance.py:1957} INFO - Dependencies all met for dep_context=non-requeueable deps ti=<TaskInstance: tsunami_etl.extract_task scheduled__2024-01-01T12:00:00+00:00 [queued]>
[2024-02-27T17:00:13.551+0000] {taskinstance.py:1957} INFO - Dependencies all met for dep_context=requeueable deps ti=<TaskInstance: tsunami_etl.extract_task scheduled__2024-01-01T12:00:00+00:00 [queued]>
[2024-02-27T17:00:13.551+0000] {taskinstance.py:2171} INFO - Starting attempt 1 of 2
[2024-02-27T17:00:13.556+0000] {taskinstance.py:2192} INFO - Executing <Task(PythonOperator): extract_task> on 2024-01-01 12:00:00+00:00
[2024-02-27T17:00:13.560+0000] {standard_task_runner.py:60} INFO - Started process 380 to run task
[2024-02-27T17:00:13.563+0000] {standard_task_runner.py:87} INFO - Running: ['airflow', 'tasks', 'run', 'tsunami_etl', 'extract_task', 'scheduled__2024-01-01T12:00:00+00:00', '--job-id', '15', '--raw', '--subdir', 'DAGS_FOLDER/tsunami_etl.py', '--cfg-path', '/tmp/tmpc23q4av4']
[2024-02-27T17:00:13.565+0000] {standard_task_runner.py:88} INFO - Job 15: Subtask extract_task
[2024-02-27T17:00:13.586+0000] {task_command.py:423} INFO - Running <TaskInstance: tsunami_etl.extract_task scheduled__2024-01-01T12:00:00+00:00 [running]> on host 45e004960ef9
[2024-02-27T17:00:13.637+0000] {taskinstance.py:2481} INFO - Exporting env vars: AIRFLOW_CTX_DAG_OWNER='airflow' AIRFLOW_CTX_DAG_ID='tsunami_etl' AIRFLOW_CTX_TASK_ID='extract_task' AIRFLOW_CTX_EXECUTION_DATE='2024-01-01T12:00:00+00:00' AIRFLOW_CTX_TRY_NUMBER='1' AIRFLOW_CTX_DAG_RUN_ID='scheduled__2024-01-01T12:00:00+00:00'
[2024-02-27T17:00:13.638+0000] {taskinstance.py:2699} ERROR - Task failed with exception
Traceback (most recent call last):
  File "/home/airflow/.local/lib/python3.8/site-packages/airflow/models/taskinstance.py", line 433, in _execute_task
    result = execute_callable(context=context, **execute_callable_kwargs)
  File "/home/airflow/.local/lib/python3.8/site-packages/airflow/operators/python.py", line 199, in execute
    return_value = self.execute_callable()
  File "/home/airflow/.local/lib/python3.8/site-packages/airflow/operators/python.py", line 216, in execute_callable
    return self.python_callable(*self.op_args, **self.op_kwargs)
  File "/opt/airflow/dags/tsunami_etl.py", line 46, in extract_tsunami
    GCPCredentials = service_account.Credentials.from_service_account_file(f"../auth/json/{CREDENTIALS_FILE}")
  File "/home/airflow/.local/lib/python3.8/site-packages/google/oauth2/service_account.py", line 257, in from_service_account_file
    info, signer = _service_account_info.from_filename(
  File "/home/airflow/.local/lib/python3.8/site-packages/google/auth/_service_account_info.py", line 78, in from_filename
    with io.open(filename, "r", encoding="utf-8") as json_file:
FileNotFoundError: [Errno 2] No such file or directory: '../auth/json/None'
[2024-02-27T17:00:13.644+0000] {taskinstance.py:1138} INFO - Marking task as UP_FOR_RETRY. dag_id=tsunami_etl, task_id=extract_task, execution_date=20240101T120000, start_date=20240227T170013, end_date=20240227T170013
[2024-02-27T17:00:13.652+0000] {standard_task_runner.py:107} ERROR - Failed to execute job 15 for task extract_task ([Errno 2] No such file or directory: '../auth/json/None'; 380)
[2024-02-27T17:00:13.664+0000] {local_task_job_runner.py:234} INFO - Task exited with return code 1
[2024-02-27T17:00:13.676+0000] {taskinstance.py:3281} INFO - 0 downstream tasks scheduled from follow-on schedule check
[2024-02-27T17:04:30.156+0000] {taskinstance.py:1957} INFO - Dependencies all met for dep_context=non-requeueable deps ti=<TaskInstance: tsunami_etl.extract_task scheduled__2024-01-01T12:00:00+00:00 [queued]>
[2024-02-27T17:04:30.159+0000] {taskinstance.py:1957} INFO - Dependencies all met for dep_context=requeueable deps ti=<TaskInstance: tsunami_etl.extract_task scheduled__2024-01-01T12:00:00+00:00 [queued]>
[2024-02-27T17:04:30.159+0000] {taskinstance.py:2171} INFO - Starting attempt 1 of 2
[2024-02-27T17:04:30.164+0000] {taskinstance.py:2192} INFO - Executing <Task(PythonOperator): extract_task> on 2024-01-01 12:00:00+00:00
[2024-02-27T17:04:30.167+0000] {standard_task_runner.py:60} INFO - Started process 589 to run task
[2024-02-27T17:04:30.169+0000] {standard_task_runner.py:87} INFO - Running: ['airflow', 'tasks', 'run', 'tsunami_etl', 'extract_task', 'scheduled__2024-01-01T12:00:00+00:00', '--job-id', '30', '--raw', '--subdir', 'DAGS_FOLDER/tsunami_etl.py', '--cfg-path', '/tmp/tmpvf6f047o']
[2024-02-27T17:04:30.170+0000] {standard_task_runner.py:88} INFO - Job 30: Subtask extract_task
[2024-02-27T17:04:30.186+0000] {task_command.py:423} INFO - Running <TaskInstance: tsunami_etl.extract_task scheduled__2024-01-01T12:00:00+00:00 [running]> on host 45e004960ef9
[2024-02-27T17:04:30.208+0000] {taskinstance.py:2481} INFO - Exporting env vars: AIRFLOW_CTX_DAG_OWNER='airflow' AIRFLOW_CTX_DAG_ID='tsunami_etl' AIRFLOW_CTX_TASK_ID='extract_task' AIRFLOW_CTX_EXECUTION_DATE='2024-01-01T12:00:00+00:00' AIRFLOW_CTX_TRY_NUMBER='1' AIRFLOW_CTX_DAG_RUN_ID='scheduled__2024-01-01T12:00:00+00:00'
[2024-02-27T17:04:30.209+0000] {taskinstance.py:2699} ERROR - Task failed with exception
Traceback (most recent call last):
  File "/home/airflow/.local/lib/python3.8/site-packages/airflow/models/taskinstance.py", line 433, in _execute_task
    result = execute_callable(context=context, **execute_callable_kwargs)
  File "/home/airflow/.local/lib/python3.8/site-packages/airflow/operators/python.py", line 199, in execute
    return_value = self.execute_callable()
  File "/home/airflow/.local/lib/python3.8/site-packages/airflow/operators/python.py", line 216, in execute_callable
    return self.python_callable(*self.op_args, **self.op_kwargs)
  File "/opt/airflow/dags/tsunami_etl.py", line 42, in extract_tsunami
    GCPCredentials = service_account.Credentials.from_service_account_file(f"../auth/json/{CREDENTIALS_FILE}")
  File "/home/airflow/.local/lib/python3.8/site-packages/google/oauth2/service_account.py", line 257, in from_service_account_file
    info, signer = _service_account_info.from_filename(
  File "/home/airflow/.local/lib/python3.8/site-packages/google/auth/_service_account_info.py", line 78, in from_filename
    with io.open(filename, "r", encoding="utf-8") as json_file:
FileNotFoundError: [Errno 2] No such file or directory: '../auth/json/None'
[2024-02-27T17:04:30.211+0000] {taskinstance.py:1138} INFO - Marking task as UP_FOR_RETRY. dag_id=tsunami_etl, task_id=extract_task, execution_date=20240101T120000, start_date=20240227T170430, end_date=20240227T170430
[2024-02-27T17:04:30.215+0000] {standard_task_runner.py:107} ERROR - Failed to execute job 30 for task extract_task ([Errno 2] No such file or directory: '../auth/json/None'; 589)
[2024-02-27T17:04:30.225+0000] {local_task_job_runner.py:234} INFO - Task exited with return code 1
[2024-02-27T17:04:30.234+0000] {taskinstance.py:3281} INFO - 0 downstream tasks scheduled from follow-on schedule check
[2024-02-27T17:06:34.550+0000] {taskinstance.py:1957} INFO - Dependencies all met for dep_context=non-requeueable deps ti=<TaskInstance: tsunami_etl.extract_task scheduled__2024-01-01T12:00:00+00:00 [queued]>
[2024-02-27T17:06:34.553+0000] {taskinstance.py:1957} INFO - Dependencies all met for dep_context=requeueable deps ti=<TaskInstance: tsunami_etl.extract_task scheduled__2024-01-01T12:00:00+00:00 [queued]>
[2024-02-27T17:06:34.553+0000] {taskinstance.py:2171} INFO - Starting attempt 1 of 2
[2024-02-27T17:06:34.559+0000] {taskinstance.py:2192} INFO - Executing <Task(PythonOperator): extract_task> on 2024-01-01 12:00:00+00:00
[2024-02-27T17:06:34.561+0000] {standard_task_runner.py:60} INFO - Started process 781 to run task
[2024-02-27T17:06:34.563+0000] {standard_task_runner.py:87} INFO - Running: ['airflow', 'tasks', 'run', 'tsunami_etl', 'extract_task', 'scheduled__2024-01-01T12:00:00+00:00', '--job-id', '46', '--raw', '--subdir', 'DAGS_FOLDER/tsunami_etl.py', '--cfg-path', '/tmp/tmpy4l2k6pc']
[2024-02-27T17:06:34.565+0000] {standard_task_runner.py:88} INFO - Job 46: Subtask extract_task
[2024-02-27T17:06:34.585+0000] {task_command.py:423} INFO - Running <TaskInstance: tsunami_etl.extract_task scheduled__2024-01-01T12:00:00+00:00 [running]> on host 45e004960ef9
[2024-02-27T17:06:34.620+0000] {taskinstance.py:2481} INFO - Exporting env vars: AIRFLOW_CTX_DAG_OWNER='airflow' AIRFLOW_CTX_DAG_ID='tsunami_etl' AIRFLOW_CTX_TASK_ID='extract_task' AIRFLOW_CTX_EXECUTION_DATE='2024-01-01T12:00:00+00:00' AIRFLOW_CTX_TRY_NUMBER='1' AIRFLOW_CTX_DAG_RUN_ID='scheduled__2024-01-01T12:00:00+00:00'
[2024-02-27T17:06:34.621+0000] {taskinstance.py:2699} ERROR - Task failed with exception
Traceback (most recent call last):
  File "/home/airflow/.local/lib/python3.8/site-packages/airflow/models/taskinstance.py", line 433, in _execute_task
    result = execute_callable(context=context, **execute_callable_kwargs)
  File "/home/airflow/.local/lib/python3.8/site-packages/airflow/operators/python.py", line 199, in execute
    return_value = self.execute_callable()
  File "/home/airflow/.local/lib/python3.8/site-packages/airflow/operators/python.py", line 216, in execute_callable
    return self.python_callable(*self.op_args, **self.op_kwargs)
  File "/opt/airflow/dags/tsunami_etl.py", line 42, in extract_tsunami
    GCPCredentials = service_account.Credentials.from_service_account_file(f"../auth/json/credentials.json")
  File "/home/airflow/.local/lib/python3.8/site-packages/google/oauth2/service_account.py", line 257, in from_service_account_file
    info, signer = _service_account_info.from_filename(
  File "/home/airflow/.local/lib/python3.8/site-packages/google/auth/_service_account_info.py", line 78, in from_filename
    with io.open(filename, "r", encoding="utf-8") as json_file:
FileNotFoundError: [Errno 2] No such file or directory: '../auth/json/credentials.json'
[2024-02-27T17:06:34.624+0000] {taskinstance.py:1138} INFO - Marking task as UP_FOR_RETRY. dag_id=tsunami_etl, task_id=extract_task, execution_date=20240101T120000, start_date=20240227T170634, end_date=20240227T170634
[2024-02-27T17:06:34.628+0000] {standard_task_runner.py:107} ERROR - Failed to execute job 46 for task extract_task ([Errno 2] No such file or directory: '../auth/json/credentials.json'; 781)
[2024-02-27T17:06:34.661+0000] {local_task_job_runner.py:234} INFO - Task exited with return code 1
[2024-02-27T17:06:34.670+0000] {taskinstance.py:3281} INFO - 0 downstream tasks scheduled from follow-on schedule check
[2024-02-27T17:10:03.225+0000] {taskinstance.py:1957} INFO - Dependencies all met for dep_context=non-requeueable deps ti=<TaskInstance: tsunami_etl.extract_task scheduled__2024-01-01T12:00:00+00:00 [queued]>
[2024-02-27T17:10:03.227+0000] {taskinstance.py:1957} INFO - Dependencies all met for dep_context=requeueable deps ti=<TaskInstance: tsunami_etl.extract_task scheduled__2024-01-01T12:00:00+00:00 [queued]>
[2024-02-27T17:10:03.228+0000] {taskinstance.py:2171} INFO - Starting attempt 1 of 2
[2024-02-27T17:10:03.233+0000] {taskinstance.py:2192} INFO - Executing <Task(PythonOperator): extract_task> on 2024-01-01 12:00:00+00:00
[2024-02-27T17:10:03.237+0000] {standard_task_runner.py:60} INFO - Started process 980 to run task
[2024-02-27T17:10:03.240+0000] {standard_task_runner.py:87} INFO - Running: ['airflow', 'tasks', 'run', 'tsunami_etl', 'extract_task', 'scheduled__2024-01-01T12:00:00+00:00', '--job-id', '14', '--raw', '--subdir', 'DAGS_FOLDER/tsunami_etl.py', '--cfg-path', '/tmp/tmpxipyjkp3']
[2024-02-27T17:10:03.242+0000] {standard_task_runner.py:88} INFO - Job 14: Subtask extract_task
[2024-02-27T17:10:03.271+0000] {task_command.py:423} INFO - Running <TaskInstance: tsunami_etl.extract_task scheduled__2024-01-01T12:00:00+00:00 [running]> on host 45e004960ef9
[2024-02-27T17:10:03.296+0000] {taskinstance.py:2481} INFO - Exporting env vars: AIRFLOW_CTX_DAG_OWNER='airflow' AIRFLOW_CTX_DAG_ID='tsunami_etl' AIRFLOW_CTX_TASK_ID='extract_task' AIRFLOW_CTX_EXECUTION_DATE='2024-01-01T12:00:00+00:00' AIRFLOW_CTX_TRY_NUMBER='1' AIRFLOW_CTX_DAG_RUN_ID='scheduled__2024-01-01T12:00:00+00:00'
[2024-02-27T17:10:03.297+0000] {taskinstance.py:2699} ERROR - Task failed with exception
Traceback (most recent call last):
  File "/home/airflow/.local/lib/python3.8/site-packages/airflow/models/taskinstance.py", line 433, in _execute_task
    result = execute_callable(context=context, **execute_callable_kwargs)
  File "/home/airflow/.local/lib/python3.8/site-packages/airflow/operators/python.py", line 199, in execute
    return_value = self.execute_callable()
  File "/home/airflow/.local/lib/python3.8/site-packages/airflow/operators/python.py", line 216, in execute_callable
    return self.python_callable(*self.op_args, **self.op_kwargs)
  File "/opt/airflow/dags/tsunami_etl.py", line 41, in extract_tsunami
    GCPCredentials = service_account.Credentials.from_service_account_file("credentials.json")
  File "/home/airflow/.local/lib/python3.8/site-packages/google/oauth2/service_account.py", line 257, in from_service_account_file
    info, signer = _service_account_info.from_filename(
  File "/home/airflow/.local/lib/python3.8/site-packages/google/auth/_service_account_info.py", line 78, in from_filename
    with io.open(filename, "r", encoding="utf-8") as json_file:
FileNotFoundError: [Errno 2] No such file or directory: 'credentials.json'
[2024-02-27T17:10:03.300+0000] {taskinstance.py:1138} INFO - Marking task as UP_FOR_RETRY. dag_id=tsunami_etl, task_id=extract_task, execution_date=20240101T120000, start_date=20240227T171003, end_date=20240227T171003
[2024-02-27T17:10:03.304+0000] {standard_task_runner.py:107} ERROR - Failed to execute job 14 for task extract_task ([Errno 2] No such file or directory: 'credentials.json'; 980)
[2024-02-27T17:10:03.341+0000] {local_task_job_runner.py:234} INFO - Task exited with return code 1
[2024-02-27T17:10:03.351+0000] {taskinstance.py:3281} INFO - 0 downstream tasks scheduled from follow-on schedule check
[2024-02-27T18:10:02.641+0000] {taskinstance.py:1957} INFO - Dependencies all met for dep_context=non-requeueable deps ti=<TaskInstance: tsunami_etl.extract_task scheduled__2024-01-01T12:00:00+00:00 [queued]>
[2024-02-27T18:10:02.644+0000] {taskinstance.py:1957} INFO - Dependencies all met for dep_context=requeueable deps ti=<TaskInstance: tsunami_etl.extract_task scheduled__2024-01-01T12:00:00+00:00 [queued]>
[2024-02-27T18:10:02.644+0000] {taskinstance.py:2171} INFO - Starting attempt 1 of 2
[2024-02-27T18:10:02.649+0000] {taskinstance.py:2192} INFO - Executing <Task(PythonOperator): extract_task> on 2024-01-01 12:00:00+00:00
[2024-02-27T18:10:02.652+0000] {standard_task_runner.py:60} INFO - Started process 500 to run task
[2024-02-27T18:10:02.655+0000] {standard_task_runner.py:87} INFO - Running: ['airflow', 'tasks', 'run', 'tsunami_etl', 'extract_task', 'scheduled__2024-01-01T12:00:00+00:00', '--job-id', '38', '--raw', '--subdir', 'DAGS_FOLDER/tsunami_etl.py', '--cfg-path', '/tmp/tmpfg8s4g_g']
[2024-02-27T18:10:02.656+0000] {standard_task_runner.py:88} INFO - Job 38: Subtask extract_task
[2024-02-27T18:10:02.676+0000] {task_command.py:423} INFO - Running <TaskInstance: tsunami_etl.extract_task scheduled__2024-01-01T12:00:00+00:00 [running]> on host cf5ca63d0f74
[2024-02-27T18:10:02.701+0000] {taskinstance.py:2481} INFO - Exporting env vars: AIRFLOW_CTX_DAG_OWNER='airflow' AIRFLOW_CTX_DAG_ID='tsunami_etl' AIRFLOW_CTX_TASK_ID='extract_task' AIRFLOW_CTX_EXECUTION_DATE='2024-01-01T12:00:00+00:00' AIRFLOW_CTX_TRY_NUMBER='1' AIRFLOW_CTX_DAG_RUN_ID='scheduled__2024-01-01T12:00:00+00:00'
[2024-02-27T18:10:02.702+0000] {taskinstance.py:2699} ERROR - Task failed with exception
Traceback (most recent call last):
  File "/home/airflow/.local/lib/python3.8/site-packages/airflow/models/taskinstance.py", line 433, in _execute_task
    result = execute_callable(context=context, **execute_callable_kwargs)
  File "/home/airflow/.local/lib/python3.8/site-packages/airflow/operators/python.py", line 199, in execute
    return_value = self.execute_callable()
  File "/home/airflow/.local/lib/python3.8/site-packages/airflow/operators/python.py", line 216, in execute_callable
    return self.python_callable(*self.op_args, **self.op_kwargs)
  File "/opt/airflow/dags/tsunami_etl.py", line 42, in extract_tsunami
    GCPCredentials = service_account.Credentials.from_service_account_file(credentials_path)
  File "/home/airflow/.local/lib/python3.8/site-packages/google/oauth2/service_account.py", line 257, in from_service_account_file
    info, signer = _service_account_info.from_filename(
  File "/home/airflow/.local/lib/python3.8/site-packages/google/auth/_service_account_info.py", line 78, in from_filename
    with io.open(filename, "r", encoding="utf-8") as json_file:
FileNotFoundError: [Errno 2] No such file or directory: './credentials.json'
[2024-02-27T18:10:02.704+0000] {taskinstance.py:1138} INFO - Marking task as UP_FOR_RETRY. dag_id=tsunami_etl, task_id=extract_task, execution_date=20240101T120000, start_date=20240227T181002, end_date=20240227T181002
[2024-02-27T18:10:02.708+0000] {standard_task_runner.py:107} ERROR - Failed to execute job 38 for task extract_task ([Errno 2] No such file or directory: './credentials.json'; 500)
[2024-02-27T18:10:02.712+0000] {local_task_job_runner.py:234} INFO - Task exited with return code 1
[2024-02-27T18:10:02.717+0000] {taskinstance.py:3281} INFO - 0 downstream tasks scheduled from follow-on schedule check
[2024-02-27T18:40:01.527+0000] {taskinstance.py:1957} INFO - Dependencies all met for dep_context=non-requeueable deps ti=<TaskInstance: tsunami_etl.extract_task scheduled__2024-01-01T12:00:00+00:00 [queued]>
[2024-02-27T18:40:01.530+0000] {taskinstance.py:1957} INFO - Dependencies all met for dep_context=requeueable deps ti=<TaskInstance: tsunami_etl.extract_task scheduled__2024-01-01T12:00:00+00:00 [queued]>
[2024-02-27T18:40:01.531+0000] {taskinstance.py:2171} INFO - Starting attempt 1 of 2
[2024-02-27T18:40:01.536+0000] {taskinstance.py:2192} INFO - Executing <Task(PythonOperator): extract_task> on 2024-01-01 12:00:00+00:00
[2024-02-27T18:40:01.540+0000] {standard_task_runner.py:60} INFO - Started process 1205 to run task
[2024-02-27T18:40:01.542+0000] {standard_task_runner.py:87} INFO - Running: ['airflow', 'tasks', 'run', 'tsunami_etl', 'extract_task', 'scheduled__2024-01-01T12:00:00+00:00', '--job-id', '38', '--raw', '--subdir', 'DAGS_FOLDER/tsunami_etl.py', '--cfg-path', '/tmp/tmpo0xmaljn']
[2024-02-27T18:40:01.543+0000] {standard_task_runner.py:88} INFO - Job 38: Subtask extract_task
[2024-02-27T18:40:01.564+0000] {task_command.py:423} INFO - Running <TaskInstance: tsunami_etl.extract_task scheduled__2024-01-01T12:00:00+00:00 [running]> on host f8b0167ca209
[2024-02-27T18:40:01.591+0000] {taskinstance.py:2481} INFO - Exporting env vars: AIRFLOW_CTX_DAG_OWNER='airflow' AIRFLOW_CTX_DAG_ID='tsunami_etl' AIRFLOW_CTX_TASK_ID='extract_task' AIRFLOW_CTX_EXECUTION_DATE='2024-01-01T12:00:00+00:00' AIRFLOW_CTX_TRY_NUMBER='1' AIRFLOW_CTX_DAG_RUN_ID='scheduled__2024-01-01T12:00:00+00:00'
[2024-02-27T18:40:01.592+0000] {taskinstance.py:2699} ERROR - Task failed with exception
Traceback (most recent call last):
  File "/home/airflow/.local/lib/python3.8/site-packages/airflow/models/taskinstance.py", line 433, in _execute_task
    result = execute_callable(context=context, **execute_callable_kwargs)
  File "/home/airflow/.local/lib/python3.8/site-packages/airflow/operators/python.py", line 199, in execute
    return_value = self.execute_callable()
  File "/home/airflow/.local/lib/python3.8/site-packages/airflow/operators/python.py", line 216, in execute_callable
    return self.python_callable(*self.op_args, **self.op_kwargs)
  File "/opt/airflow/dags/tsunami_etl.py", line 44, in extract_tsunami
    with open(credentials_path, "r") as file:
FileNotFoundError: [Errno 2] No such file or directory: './credentials.json'
[2024-02-27T18:40:01.594+0000] {taskinstance.py:1138} INFO - Marking task as UP_FOR_RETRY. dag_id=tsunami_etl, task_id=extract_task, execution_date=20240101T120000, start_date=20240227T184001, end_date=20240227T184001
[2024-02-27T18:40:01.599+0000] {standard_task_runner.py:107} ERROR - Failed to execute job 38 for task extract_task ([Errno 2] No such file or directory: './credentials.json'; 1205)
[2024-02-27T18:40:01.640+0000] {local_task_job_runner.py:234} INFO - Task exited with return code 1
[2024-02-27T18:40:01.649+0000] {taskinstance.py:3281} INFO - 0 downstream tasks scheduled from follow-on schedule check
[2024-02-27T18:47:20.611+0000] {taskinstance.py:1957} INFO - Dependencies all met for dep_context=non-requeueable deps ti=<TaskInstance: tsunami_etl.extract_task scheduled__2024-01-01T12:00:00+00:00 [queued]>
[2024-02-27T18:47:20.615+0000] {taskinstance.py:1957} INFO - Dependencies all met for dep_context=requeueable deps ti=<TaskInstance: tsunami_etl.extract_task scheduled__2024-01-01T12:00:00+00:00 [queued]>
[2024-02-27T18:47:20.615+0000] {taskinstance.py:2171} INFO - Starting attempt 1 of 2
[2024-02-27T18:47:20.622+0000] {taskinstance.py:2192} INFO - Executing <Task(PythonOperator): extract_task> on 2024-01-01 12:00:00+00:00
[2024-02-27T18:47:20.626+0000] {standard_task_runner.py:60} INFO - Started process 508 to run task
[2024-02-27T18:47:20.628+0000] {standard_task_runner.py:87} INFO - Running: ['airflow', 'tasks', 'run', 'tsunami_etl', 'extract_task', 'scheduled__2024-01-01T12:00:00+00:00', '--job-id', '38', '--raw', '--subdir', 'DAGS_FOLDER/tsunami_etl.py', '--cfg-path', '/tmp/tmpsdapdsbk']
[2024-02-27T18:47:20.630+0000] {standard_task_runner.py:88} INFO - Job 38: Subtask extract_task
[2024-02-27T18:47:20.647+0000] {task_command.py:423} INFO - Running <TaskInstance: tsunami_etl.extract_task scheduled__2024-01-01T12:00:00+00:00 [running]> on host c200f435f34d
[2024-02-27T18:47:20.670+0000] {taskinstance.py:2481} INFO - Exporting env vars: AIRFLOW_CTX_DAG_OWNER='airflow' AIRFLOW_CTX_DAG_ID='tsunami_etl' AIRFLOW_CTX_TASK_ID='extract_task' AIRFLOW_CTX_EXECUTION_DATE='2024-01-01T12:00:00+00:00' AIRFLOW_CTX_TRY_NUMBER='1' AIRFLOW_CTX_DAG_RUN_ID='scheduled__2024-01-01T12:00:00+00:00'
[2024-02-27T18:47:20.671+0000] {taskinstance.py:2699} ERROR - Task failed with exception
Traceback (most recent call last):
  File "/home/airflow/.local/lib/python3.8/site-packages/airflow/models/taskinstance.py", line 433, in _execute_task
    result = execute_callable(context=context, **execute_callable_kwargs)
  File "/home/airflow/.local/lib/python3.8/site-packages/airflow/operators/python.py", line 199, in execute
    return_value = self.execute_callable()
  File "/home/airflow/.local/lib/python3.8/site-packages/airflow/operators/python.py", line 216, in execute_callable
    return self.python_callable(*self.op_args, **self.op_kwargs)
  File "/opt/airflow/dags/tsunami_etl.py", line 44, in extract_tsunami
    with open(credentials_path, "r") as file:
FileNotFoundError: [Errno 2] No such file or directory: './credentials.json'
[2024-02-27T18:47:20.673+0000] {taskinstance.py:1138} INFO - Marking task as UP_FOR_RETRY. dag_id=tsunami_etl, task_id=extract_task, execution_date=20240101T120000, start_date=20240227T184720, end_date=20240227T184720
[2024-02-27T18:47:20.677+0000] {standard_task_runner.py:107} ERROR - Failed to execute job 38 for task extract_task ([Errno 2] No such file or directory: './credentials.json'; 508)
[2024-02-27T18:47:20.681+0000] {local_task_job_runner.py:234} INFO - Task exited with return code 1
[2024-02-27T18:47:20.687+0000] {taskinstance.py:3281} INFO - 0 downstream tasks scheduled from follow-on schedule check
